Workbook

Sheet Fielding (2)
H2: Team A | I2: Team A | J2: Team A | K2: Team A | L2: Team A | M2: Team A | N2: Team A | O2: Team A | P2: Team A
A3: Position | B3: Name | C3: Range/Blocking | D3: Error/Framing | E3: Arm | F3: Turn DP | G3: Games | H3: W | I3: L | J3: Runs scored | K3: Runs allowed | L3: winpct | M3: run score/G | N3: run conc/G | O3: win/162 delta | P3: run/162 delta
A4: SS | B4: Baseline | C4: 60 | D4: 60 | E4: 55 | F4: 50 | G4: 100000 | H4: 50231 | I4: =G4-H4 -> 49769 | J4: 434612 | K4: 433939 | L4: =H4/G4 -> 0.50231 | M4: =J4/G4 -> 4.34612 | N4: =K4/G4 -> 4.33939
A5: SS | B5: Baseline | C5: 60 | D5: 60 | E5: 55 | F5: 50 | G5: 100000 | H5: 50093 | I5: =G5-H5 -> 49907 | J5: 434305 | K5: 433615 | L5: =H5/G5 -> 0.50093 | M5: =J5/G5 -> 4.34305 | N5: =K5/G5 -> 4.33615
A6: SS | B6: Baseline | C6: 60 | D6: 60 | E6: 55 | F6: 50 | G6: 100000 | H6: 50118 | I6: =G6-H6 -> 49882 | J6: 434377 | K6: 434430 | L6: =H6/G6 -> 0.50118 | M6: =J6/G6 -> 4.34377 | N6: =K6/G6 -> 4.3443
A7: SS | B7: Baseline Average | C7: 60 | D7: 60 | E7: 55 | F7: 50 | G7: 100000 | H7: =AVERAGE(H4:H6) -> 50147.333 | I7: =G7-H7 -> 49852.667 | J7: =AVERAGE(J4:J6) -> 434431.33 | K7: =AVERAGE(K4:K6) -> 433994.67 | L7: =H7/G7 -> 0.50147333 | M7: =J7/G7 -> 4.3443133 | N7: =K7/G7 -> 4.3399467 | O7: n/a | P7: n/a
A8: SS | B8: =_xlfn.CONCAT("RNG",C8,"xERR",D8,"xARM",E8,"xTDP",F8) -> RNG40xERR60xARM55xTDP50 | C8: 40 | D8: 60 | E8: 55 | F8: 50 | G8: 100000 | H8: 49543 | I8: =G8-H8 -> 50457 | J8: 434865 | K8: 440217 | L8: =H8/G8 -> 0.49543 | M8: =J8/G8 -> 4.34865 | N8: =K8/G8 -> 4.40217 | O8: =(L8-$L$7)*162 -> -0.97902 | P8: =-(N8-$N$7)*162 -> -10.08018
A9: SS | B9: =_xlfn.CONCAT("RNG",C9,"xERR",D9,"xARM",E9,"xTDP",F9) -> RNG45xERR60xARM55xTDP50 | C9: 45 | D9: 60 | E9: 55 | F9: 50 | G9: 100000 | H9: 49497 | I9: =G9-H9 -> 50503 | J9: 434811 | K9: 438342 | L9: =H9/G9 -> 0.49497 | M9: =J9/G9 -> 4.34811 | N9: =K9/G9 -> 4.38342 | O9: =(L9-$L$7)*162 -> -1.05354 | P9: =-(N9-$N$7)*162 -> -7.04268
A10: SS | B10: =_xlfn.CONCAT("RNG",C10,"xERR",D10,"xARM",E10,"xTDP",F10) -> RNG50xERR60xARM55xTDP50 | C10: 50 | D10: 60 | E10: 55 | F10: 50 | G10: 100000 | H10: 49215 | I10: =G10-H10 -> 50785 | J10: 433536 | K10: 440885 | L10: =H10/G10 -> 0.49215 | M10: =J10/G10 -> 4.33536 | N10: =K10/G10 -> 4.40885 | O10: =(L10-$L$7)*162 -> -1.51038 | P10: =-(N10-$N$7)*162 -> -11.16234
A11: SS | B11: =_xlfn.CONCAT("RNG",C11,"xERR",D11,"xARM",E11,"xTDP",F11) -> RNG55xERR60xARM55xTDP50 | C11: 55 | D11: 60 | E11: 55 | F11: 50 | G11: 100000 | H11: 49146 | I11: =G11-H11 -> 50854 | J11: 435444 | K11: 442064 | L11: =H11/G11 -> 0.49146 | M11: =J11/G11 -> 4.35444 | N11: =K11/G11 -> 4.42064 | O11: =(L11-$L$7)*162 -> -1.62216 | P11: =-(N11-$N$7)*162 -> -13.07232
A12: SS | B12: =_xlfn.CONCAT("RNG",C12,"xERR",D12,"xARM",E12,"xTDP",F12) -> RNG65xERR60xARM55xTDP50 | C12: 65 | D12: 60 | E12: 55 | F12: 50 | G12: 100000 | H12: 51849 | I12: =G12-H12 -> 48151 | J12: 434109 | K12: 416465 | L12: =H12/G12 -> 0.51849 | M12: =J12/G12 -> 4.34109 | N12: =K12/G12 -> 4.16465 | O12: =(L12-$L$7)*162 -> 2.7567 | P12: =-(N12-$N$7)*162 -> 28.39806
A13: SS | B13: =_xlfn.CONCAT("RNG",C13,"xERR",D13,"xARM",E13,"xTDP",F13) -> RNG70xERR60xARM55xTDP50 | C13: 70 | D13: 60 | E13: 55 | F13: 50 | G13: 100000 | H13: 51991 | I13: =G13-H13 -> 48009 | J13: 433680 | K13: 413888 | L13: =H13/G13 -> 0.51991 | M13: =J13/G13 -> 4.3368 | N13: =K13/G13 -> 4.13888 | O13: =(L13-$L$7)*162 -> 2.98674 | P13: =-(N13-$N$7)*162 -> 32.5728
A14: SS | B14: =_xlfn.CONCAT("RNG",C14,"xERR",D14,"xARM",E14,"xTDP",F14) -> RNG75xERR60xARM55xTDP50 | C14: 75 | D14: 60 | E14: 55 | F14: 50 | G14: 100000 | H14: 51814 | I14: =G14-H14 -> 48186 | J14: 431343 | K14: 413087 | L14: =H14/G14 -> 0.51814 | M14: =J14/G14 -> 4.31343 | N14: =K14/G14 -> 4.13087 | O14: =(L14-$L$7)*162 -> 2.7 | P14: =-(N14-$N$7)*162 -> 33.87042
A15: SS | B15: =_xlfn.CONCAT("RNG",C15,"xERR",D15,"xARM",E15,"xTDP",F15) -> RNG60xERR50xARM55xTDP50 | C15: 60 | D15: 50 | E15: 55 | F15: 50 | G15: 100000 | H15: 49866 | I15: =G15-H15 -> 50134 | J15: 434246 | K15: 436547 | L15: =H15/G15 -> 0.49866 | M15: =J15/G15 -> 4.34246 | N15: =K15/G15 -> 4.36547 | O15: =(L15-$L$7)*162 -> -0.45576 | P15: =-(N15-$N$7)*162 -> -4.13478
A16: SS | B16: =_xlfn.CONCAT("RNG",C16,"xERR",D16,"xARM",E16,"xTDP",F16) -> RNG60xERR55xARM55xTDP50 | C16: 60 | D16: 55 | E16: 55 | F16: 50 | G16: 100000 | H16: 49855 | I16: =G16-H16 -> 50145 | J16: 435110 | K16: 436472 | L16: =H16/G16 -> 0.49855 | M16: =J16/G16 -> 4.3511 | N16: =K16/G16 -> 4.36472 | O16: =(L16-$L$7)*162 -> -0.47358 | P16: =-(N16-$N$7)*162 -> -4.01328
A17: SS | B17: =_xlfn.CONCAT("RNG",C17,"xERR",D17,"xARM",E17,"xTDP",F17) -> RNG60xERR65xARM55xTDP50 | C17: 60 | D17: 65 | E17: 55 | F17: 50 | G17: 100000 | H17: 49965 | I17: =G17-H17 -> 50035 | J17: 435041 | K17: 434114 | L17: =H17/G17 -> 0.49965 | M17: =J17/G17 -> 4.35041 | N17: =K17/G17 -> 4.34114 | O17: =(L17-$L$7)*162 -> -0.29538 | P17: =-(N17-$N$7)*162 -> -0.19332
A18: SS | B18: =_xlfn.CONCAT("RNG",C18,"xERR",D18,"xARM",E18,"xTDP",F18) -> RNG60xERR70xARM55xTDP50 | C18: 60 | D18: 70 | E18: 55 | F18: 50 | G18: 100000 | H18: 50584 | I18: =G18-H18 -> 49416 | J18: 435999 | K18: 431954 | L18: =H18/G18 -> 0.50584 | M18: =J18/G18 -> 4.35999 | N18: =K18/G18 -> 4.31954 | O18: =(L18-$L$7)*162 -> 0.7074 | P18: =-(N18-$N$7)*162 -> 3.30588
A19: SS | B19: =_xlfn.CONCAT("RNG",C19,"xERR",D19,"xARM",E19,"xTDP",F19) -> RNG60xERR75xARM55xTDP50 | C19: 60 | D19: 75 | E19: 55 | F19: 50 | G19: 100000 | H19: 50331 | I19: =G19-H19 -> 49669 | J19: 436126 | K19: 432745 | L19: =H19/G19 -> 0.50331 | M19: =J19/G19 -> 4.36126 | N19: =K19/G19 -> 4.32745 | O19: =(L19-$L$7)*162 -> 0.29754 | P19: =-(N19-$N$7)*162 -> 2.02446
... A71: SS | B71: =_xlfn.CONCAT("RNG",C71,"xERR",D71,"xARM",E71,"xTDP",F71) -> RNG70xERR60xARM60xTDP50 | C71: 70 | D71: 60 | E71: 60 | F71: 50 | G71: 100000 | H71: 52140 | I71: =G71-H71 -> 47860 | J71: 434730 | K71: 414048 | L71: =H71/G71 -> 0.5214 | M71: =J71/G71 -> 4.3473 | N71: =K71/G71 -> 4.14048 | O71: =(L71-$L$7)*162 -> 3.22812 | P71: =-(N71-$N$7)*162 -> 32.3136
A72: 1B | B72: Baseline | C72: 35 | D72: 35 | E72: 40 | F72: 40 | G72: 100000 | H72: 50147.333 | I72: 49852.667 | J72: 434431.33 | K72: 433994.67 | L72: 0.50147333 | M72: 4.3443133 | N72: 4.3399467 | O72: n/a | P72: n/a
A73: 1B | B73: =_xlfn.CONCAT("RNG",C73,"xERR",D73,"xARM",E73,"xTDP",F73) -> RNG20xERR35xARM40xTDP40 | C73: 20 | D73: 35 | E73: 40 | F73: 40 | G73: 100000 | H73: 49785 | I73: =G73-H73 -> 50215 | J73: 431980 | K73: 435007 | L73: =H73/G73 -> 0.49785 | M73: =J73/G73 -> 4.3198 | N73: =K73/G73 -> 4.35007 | O73: =(L73-$L$7)*162 -> -0.58698 | P73: =-(N73-$N$7)*162 -> -1.63998
A74: 1B | B74: =_xlfn.CONCAT("RNG",C74,"xERR",D74,"xARM",E74,"xTDP",F74) -> RNG30xERR35xARM40xTDP40 | C74: 30 | D74: 35 | E74: 40 | F74: 40 | G74: 100000 | H74: 49649 | I74: =G74-H74 -> 50351 | J74: 434021 | K74: 436272 | L74: =H74/G74 -> 0.49649 | M74: =J74/G74 -> 4.34021 | N74: =K74/G74 -> 4.36272 | O74: =(L74-$L$7)*162 -> -0.8073 | P74: =-(N74-$N$7)*162 -> -3.68928
A75: 1B | B75: =_xlfn.CONCAT("RNG",C75,"xERR",D75,"xARM",E75,"xTDP",F75) -> RNG40xERR35xARM40xTDP40 | C75: 40 | D75: 35 | E75: 40 | F75: 40 | G75: 100000 | H75: 50370 | I75: =G75-H75 -> 49630 | J75: 435324 | K75: 433571 | L75: =H75/G75 -> 0.5037 | M75: =J75/G75 -> 4.35324 | N75: =K75/G75 -> 4.33571 | O75: =(L75-$L$7)*162 -> 0.36072 | P75: =-(N75-$N$7)*162 -> 0.68634
A76: 1B | B76: =_xlfn.CONCAT("RNG",C76,"xERR",D76,"xARM",E76,"xTDP",F76) -> RNG45xERR35xARM40xTDP40 | C76: 45 | D76: 35 | E76: 40 | F76: 40 | G76: 100000 | H76: 50354 | I76: =G76-H76 -> 49646 | J76: 432861 | K76: 431648 | L76: =H76/G76 -> 0.50354 | M76: =J76/G76 -> 4.32861 | N76: =K76/G76 -> 4.31648 | O76: =(L76-$L$7)*162 -> 0.3348 | P76: =-(N76-$N$7)*162 -> 3.8016
A77: 1B | B77: =_xlfn.CONCAT("RNG",C77,"xERR",D77,"xARM",E77,"xTDP",F77) -> RNG50xERR35xARM40xTDP40 | C77: 50 | D77: 35 | E77: 40 | F77: 40 | G77: 100000 | H77: 50084 | I77: =G77-H77 -> 49916 | J77: 435040 | K77: 433487 | L77: =H77/G77 -> 0.50084 | M77: =J77/G77 -> 4.3504 | N77: =K77/G77 -> 4.33487 | O77: =(L77-$L$7)*162 -> -0.1026 | P77: =-(N77-$N$7)*162 -> 0.82242
A78: 1B | B78: =_xlfn.CONCAT("RNG",C78,"xERR",D78,"xARM",E78,"xTDP",F78) -> RNG35xERR20xARM40xTDP40 | C78: 35 | D78: 20 | E78: 40 | F78: 40 | G78: 100000 | H78: 49809 | I78: =G78-H78 -> 50191 | J78: 433003 | K78: 435255 | L78: =H78/G78 -> 0.49809 | M78: =J78/G78 -> 4.33003 | N78: =K78/G78 -> 4.35255 | O78: =(L78-$L$7)*162 -> -0.5481 | P78: =-(N78-$N$7)*162 -> -2.04174
A79: 1B | B79: =_xlfn.CONCAT("RNG",C79,"xERR",D79,"xARM",E79,"xTDP",F79) -> RNG35xERR30xARM40xTDP40 | C79: 35 | D79: 30 | E79: 40 | F79: 40 | G79: 100000 | H79: 50204 | I79: =G79-H79 -> 49796 | J79: 434831 | K79: 433581 | L79: =H79/G79 -> 0.50204 | M79: =J79/G79 -> 4.34831 | N79: =K79/G79 -> 4.33581 | O79: =(L79-$L$7)*162 -> 0.0918 | P79: =-(N79-$N$7)*162 -> 0.67014
A80: 1B | B80: =_xlfn.CONCAT("RNG",C80,"xERR",D80,"xARM",E80,"xTDP",F80) -> RNG35xERR40xARM40xTDP40 | C80: 35 | D80: 40 | E80: 40 | F80: 40 | G80: 100000 | H80: 50104 | I80: =G80-H80 -> 49896 | J80: 433688 | K80: 433280 | L80: =H80/G80 -> 0.50104 | M80: =J80/G80 -> 4.33688 | N80: =K80/G80 -> 4.3328 | O80: =(L80-$L$7)*162 -> -0.0702 | P80: =-(N80-$N$7)*162 -> 1.15776
A81: 1B | B81: =_xlfn.CONCAT("RNG",C81,"xERR",D81,"xARM",E81,"xTDP",F81) -> RNG35xERR50xARM40xTDP40 | C81: 35 | D81: 50 | E81: 40 | F81: 40 | G81: 100000 | H81: 50127 | I81: =G81-H81 -> 49873 | J81: 434898 | K81: 435363 | L81: =H81/G81 -> 0.50127 | M81: =J81/G81 -> 4.34898 | N81: =K81/G81 -> 4.35363 | O81: =(L81-$L$7)*162 -> -0.03294 | P81: =-(N81-$N$7)*162 -> -2.2167
A82: 1B | B82: =_xlfn.CONCAT("RNG",C82,"xERR",D82,"xARM",E82,"xTDP",F82) -> RNG35xERR60xARM40xTDP40 | C82: 35 | D82: 60 | E82: 40 | F82: 40 | G82: 100000 | H82: 49836 | I82: =G82-H82 -> 50164 | J82: 434831 | K82: 435131 | L82: =H82/G82 -> 0.49836 | M82: =J82/G82 -> 4.34831 | N82: =K82/G82 -> 4.35131 | O82: =(L82-$L$7)*162 -> -0.50436 | P82: =-(N82-$N$7)*162 -> -1.84086
A83: 1B | B83: =_xlfn.CONCAT("RNG",C83,"xERR",D83,"xARM",E83,"xTDP",F83) -> RNG40xERR40xARM40xTDP40 | C83: 40 | D83: 40 | E83: 40 | F83: 40 | G83: 100000 | H83: 50112 | I83: =G83-H83 -> 49888 | J83: 434556 | K83: 433551 | L83: =H83/G83 -> 0.50112 | M83: =J83/G83 -> 4.34556 | N83: =K83/G83 -> 4.33551 | O83: =(L83-$L$7)*162 -> -0.05724 | P83: =-(N83-$N$7)*162 -> 0.71874
A84: 1B | B84: =_xlfn.CONCAT("RNG",C84,"xERR",D84,"xARM",E84,"xTDP",F84) -> RNG50xERR50xARM50xTDP50 | C84: 50 | D84: 50 | E84: 50 | F84: 50 | G84: 100000 | H84: 50163 | I84: =G84-H84 -> 49837 | J84: 433538 | K84: 431491 | L84: =H84/G84 -> 0.50163 | M84: =J84/G84 -> 4.33538 | N84: =K84/G84 -> 4.31491 | O84: =(L84-$L$7)*162 -> 0.02538 | P84: =-(N84-$N$7)*162 -> 4.05594
A85: 2B | B85: Baseline | C85: 50 | D85: 55 | E85: 50 | F85: 55 | G85: 100000 | H85: 50147.333 | I85: 49852.667 | J85: 434431.33 | K85: 433994.67 | L85: 0.50147333 | M85: 4.3443133 | N85: 4.3399467 | O85: n/a | P85: n/a
A86: 2B | B86: =_xlfn.CONCAT("RNG",C86,"xERR",D86,"xARM",E86,"xTDP",F86) -> RNG40xERR55xARM50xTDP55 | C86: 40 | D86: 55 | E86: 50 | F86: 55 | G86: 100000 | H86: 49985 | I86: =G86-H86 -> 50015 | J86: 435642 | K86: 436419 | L86: =H86/G86 -> 0.49985 | M86: =J86/G86 -> 4.35642 | N86: =K86/G86 -> 4.36419 | O86: =(L86-$L$7)*162 -> -0.26298 | P86: =-(N86-$N$7)*162 -> -3.92742
A87: 2B | B87: =_xlfn.CONCAT("RNG",C87,"xERR",D87,"xARM",E87,"xTDP",F87) -> RNG55xERR55xARM50xTDP55 | C87: 55 | D87: 55 | E87: 50 | F87: 55 | G87: 100000 | H87: 51016 | I87: =G87-H87 -> 48984 | J87: 435847 | K87: 426798 | L87: =H87/G87 -> 0.51016 | M87: =J87/G87 -> 4.35847 | N87: =K87/G87 -> 4.26798 | O87: =(L87-$L$7)*162 -> 1.40724 | P87: =-(N87-$N$7)*162 -> 11.6586
A88: 2B | B88: =_xlfn.CONCAT("RNG",C88,"xERR",D88,"xARM",E88,"xTDP",F88) -> RNG60xERR55xARM50xTDP55 | C88: 60 | D88: 55 | E88: 50 | F88: 55 | G88: 100000 | H88: 50816 | I88: =G88-H88 -> 49184 | J88: 434030 | K88: 426670 | L88: =H88/G88 -> 0.50816 | M88: =J88/G88 -> 4.3403 | N88: =K88/G88 -> 4.2667 | O88: =(L88-$L$7)*162 -> 1.08324 | P88: =-(N88-$N$7)*162 -> 11.86596
A89: 2B | B89: =_xlfn.CONCAT("RNG",C89,"xERR",D89,"xARM",E89,"xTDP",F89) -> RNG65xERR55xARM50xTDP55 | C89: 65 | D89: 55 | E89: 50 | F89: 55 | G89: 100000 | H89: 51001 | I89: =G89-H89 -> 48999 | J89: 433625 | K89: 425328 | L89: =H89/G89 -> 0.51001 | M89: =J89/G89 -> 4.33625 | N89: =K89/G89 -> 4.25328 | O89: =(L89-$L$7)*162 -> 1.38294 | P89: =-(N89-$N$7)*162 -> 14.04
A90: 2B | B90: =_xlfn.CONCAT("RNG",C90,"xERR",D90,"xARM",E90,"xTDP",F90) -> RNG70xERR55xARM50xTDP55 | C90: 70 | D90: 55 | E90: 50 | F90: 55 | G90: 100000 | H90: 50811 | I90: =G90-H90 -> 49189 | J90: 433670 | K90: 425315 | L90: =H90/G90 -> 0.50811 | M90: =J90/G90 -> 4.3367 | N90: =K90/G90 -> 4.25315 | O90: =(L90-$L$7)*162 -> 1.07514 | P90: =-(N90-$N$7)*162 -> 14.06106
A91: 2B | B91: =_xlfn.CONCAT("RNG",C91,"xERR",D91,"xARM",E91,"xTDP",F91) -> RNG75xERR55xARM50xTDP55 | C91: 75 | D91: 55 | E91: 50 | F91: 55 | G91: 100000 | H91: 50715 | I91: =G91-H91 -> 49285 | J91: 434090 | K91: 425781 | L91: =H91/G91 -> 0.50715 | M91: =J91/G91 -> 4.3409 | N91: =K91/G91 -> 4.25781 | O91: =(L91-$L$7)*162 -> 0.91962 | P91: =-(N91-$N$7)*162 -> 13.30614
A92: 2B | B92: =_xlfn.CONCAT("RNG",C92,"xERR",D92,"xARM",E92,"xTDP",F92) -> RNG50xERR40xARM50xTDP55 | C92: 50 | D92: 40 | E92: 50 | F92: 55 | G92: 100000 | H92: 49945 | I92: =G92-H92 -> 50055 | J92: 433834 | K92: 436366 | L92: =H92/G92 -> 0.49945 | M92: =J92/G92 -> 4.33834 | N92: =K92/G92 -> 4.36366 | O92: =(L92-$L$7)*162 -> -0.32778 | P92: =-(N92-$N$7)*162 -> -3.84156
...

Sheet Calculator
C1: 1B% | D1: 2B% | E1: 3B% | F1: HR% | G1: BB% | H1: K% | I1: GO+FO% | J1: IBB+HBP%
A2: AVK | C2: =IFERROR(_xlfn.XLOOKUP($B2,Hitters!$A$4:$A$70,Hitters!AS$4:AS$70),1) -> 1 | D2: =IFERROR(_xlfn.XLOOKUP($B2,Hitters!$A$4:$A$70,Hitters!AT$4:AT$70),1) -> 1 | E2: =IFERROR(_xlfn.XLOOKUP($B2,Hitters!$A$4:$A$70,Hitters!AU$4:AU$70),1) -> 1 | F2: =IFERROR(_xlfn.XLOOKUP($B2,Hitters!$A$4:$A$70,Hitters!AV$4:AV$70),1) -> 1 | G2: =IFERROR(_xlfn.XLOOKUP($B2,Hitters!$A$4:$A$70,Hitters!AW$4:AW$70),1) -> 1 | H2: =IFERROR(_xlfn.XLOOKUP($B2,Hitters!$A$4:$A$70,Hitters!AX$4:AX$70),1) -> 1 | I2: =IFERROR(_xlfn.XLOOKUP($B2,Hitters!$A$4:$A$70,Hitters!AY$4:AY$70),1) -> 1 | J2: 0
A3: BABIP | C3: =IFERROR(_xlfn.XLOOKUP($B3,Hitters!$A$4:$A$70,Hitters!AS$4:AS$70),1) -> 1 | D3: =IFERROR(_xlfn.XLOOKUP($B3,Hitters!$A$4:$A$70,Hitters!AT$4:AT$70),1) -> 1 | E3: =IFERROR(_xlfn.XLOOKUP($B3,Hitters!$A$4:$A$70,Hitters!AU$4:AU$70),1) -> 1 | F3: =IFERROR(_xlfn.XLOOKUP($B3,Hitters!$A$4:$A$70,Hitters!AV$4:AV$70),1) -> 1 | G3: =IFERROR(_xlfn.XLOOKUP($B3,Hitters!$A$4:$A$70,Hitters!AW$4:AW$70),1) -> 1 | H3: =IFERROR(_xlfn.XLOOKUP($B3,Hitters!$A$4:$A$70,Hitters!AX$4:AX$70),1) -> 1 | I3: =IFERROR(_xlfn.XLOOKUP($B3,Hitters!$A$4:$A$70,Hitters!AY$4:AY$70),1) -> 1 | J3: 0
A4: GAP | C4: =IFERROR(_xlfn.XLOOKUP($B4,Hitters!$A$4:$A$70,Hitters!AS$4:AS$70),1) -> 1 | D4: =IFERROR(_xlfn.XLOOKUP($B4,Hitters!$A$4:$A$70,Hitters!AT$4:AT$70),1) -> 1 | E4: =IFERROR(_xlfn.XLOOKUP($B4,Hitters!$A$4:$A$70,Hitters!AU$4:AU$70),1) -> 1 | F4: =IFERROR(_xlfn.XLOOKUP($B4,Hitters!$A$4:$A$70,Hitters!AV$4:AV$70),1) -> 1 | G4: =IFERROR(_xlfn.XLOOKUP($B4,Hitters!$A$4:$A$70,Hitters!AW$4:AW$70),1) -> 1 | H4: =IFERROR(_xlfn.XLOOKUP($B4,Hitters!$A$4:$A$70,Hitters!AX$4:AX$70),1) -> 1 | I4: =IFERROR(_xlfn.XLOOKUP($B4,Hitters!$A$4:$A$70,Hitters!AY$4:AY$70),1) -> 1 | J4: 0
A5: POW | C5: =IFERROR(_xlfn.XLOOKUP($B5,Hitters!$A$4:$A$70,Hitters!AS$4:AS$70),1) -> 1 | D5: =IFERROR(_xlfn.XLOOKUP($B5,Hitters!$A$4:$A$70,Hitters!AT$4:AT$70),1) -> 1 | E5: =IFERROR(_xlfn.XLOOKUP($B5,Hitters!$A$4:$A$70,Hitters!AU$4:AU$70),1) -> 1 | F5: =IFERROR(_xlfn.XLOOKUP($B5,Hitters!$A$4:$A$70,Hitters!AV$4:AV$70),1) -> 1 | G5: =IFERROR(_xlfn.XLOOKUP($B5,Hitters!$A$4:$A$70,Hitters!AW$4:AW$70),1) -> 1 | H5: =IFERROR(_xlfn.XLOOKUP($B5,Hitters!$A$4:$A$70,Hitters!AX$4:AX$70),1) -> 1 | I5: =IFERROR(_xlfn.XLOOKUP($B5,Hitters!$A$4:$A$70,Hitters!AY$4:AY$70),1) -> 1 | J5: 0
A6: EYE | C6: =IFERROR(_xlfn.XLOOKUP($B6,Hitters!$A$4:$A$70,Hitters!AS$4:AS$70),1) -> 1 | D6: =IFERROR(_xlfn.XLOOKUP($B6,Hitters!$A$4:$A$70,Hitters!AT$4:AT$70),1) -> 1 | E6: =IFERROR(_xlfn.XLOOKUP($B6,Hitters!$A$4:$A$70,Hitters!AU$4:AU$70),1) -> 1 | F6: =IFERROR(_xlfn.XLOOKUP($B6,Hitters!$A$4:$A$70,Hitters!AV$4:AV$70),1) -> 1 | G6: =IFERROR(_xlfn.XLOOKUP($B6,Hitters!$A$4:$A$70,Hitters!AW$4:AW$70),1) -> 1 | H6: =IFERROR(_xlfn.XLOOKUP($B6,Hitters!$A$4:$A$70,Hitters!AX$4:AX$70),1) -> 1 | I6: =IFERROR(_xlfn.XLOOKUP($B6,Hitters!$A$4:$A$70,Hitters!AY$4:AY$70),1) -> 1 | J6: 0
A7: Estimate | C7: =Hitters!AI$7*PRODUCT(C2:C6) -> 0.1572441 | D7: =Hitters!AJ$7*PRODUCT(D2:D6) -> 0.04812209 | E7: =Hitters!AK$7*PRODUCT(E2:E6) -> 0.003798916 | F7: =Hitters!AL$7*PRODUCT(F2:F6) -> 0.026301987 | G7: =Hitters!AM$7*PRODUCT(G2:G6) -> 0.073762937 | H7: =Hitters!AN$7*PRODUCT(H2:H6) -> 0.21167768 | I7: =Hitters!AO$7*PRODUCT(I2:I6) -> 0.45909229 | J7: 0.02
A8: Normalized | C8: =C7/SUM($C$7:$I$7)*0.98 -> 0.1572441 | D8: =D7/SUM($C$7:$I$7)*0.98 -> 0.04812209 | E8: =E7/SUM($C$7:$I$7)*0.98 -> 0.003798916 | F8: =F7/SUM($C$7:$I$7)*0.98 -> 0.026301987 | G8: =G7/SUM($C$7:$I$7)*0.98 -> 0.073762937 | H8: =H7/SUM($C$7:$I$7)*0.98 -> 0.21167768 | I8: =I7/SUM($C$7:$I$7)*0.98 -> 0.45909229 | J8: 0.02
A11: wOBA estimate | C11: =SUMPRODUCT(C7:H7,Hitters!AI1:AN1) -> 0.31151558
A12: WAA estimate | C12: =B14+(B15*C11) -> -0.086165856
A14: Intercept | B14: -14.02807
A15: X Variable 1 | B15: 44.755077

Sheet Hitters
AH1: WOBA weights | AI1: 0.9 | AJ1: 1.24 | AK1: 1.56 | AL1: 1.95 | AM1: 0.72
AC2: Team A | AD2: Team A | AE2: Team A | AF2: Team A | AG2: Team B | AH2: calc | AS2: Deltas | BB2: =STANDARDIZE(BB3,AVERAGE($BB$3:$BC$3,$BE$3:$BH$3),_xlfn.STDEV.P($BB$3:$BC$3,$BE$3:$BH$3)) -> -0.024373264 | BC2: =STANDARDIZE(BC3,AVERAGE($BB$3:$BC$3,$BE$3:$BH$3),_xlfn.STDEV.P($BB$3:$BC$3,$BE$3:$BH$3)) -> -0.25880708 | BE2: =STANDARDIZE(BE3,AVERAGE($BB$3:$BC$3,$BE$3:$BH$3),_xlfn.STDEV.P($BB$3:$BC$3,$BE$3:$BH$3)) -> 2.074318 | BF2: =STANDARDIZE(BF3,AVERAGE($BB$3:$BC$3,$BE$3:$BH$3),_xlfn.STDEV.P($BB$3:$BC$3,$BE$3:$BH$3)) -> 0.0095199581 | BG2: =STANDARDIZE(BG3,AVERAGE($BB$3:$BC$3,$BE$3:$BH$3),_xlfn.STDEV.P($BB$3:$BC$3,$BE$3:$BH$3)) -> -0.96496368 | BH2: =STANDARDIZE(BH3,AVERAGE($BB$3:$BC$3,$BE$3:$BH$3),_xlfn.STDEV.P($BB$3:$BC$3,$BE$3:$BH$3)) -> -0.8356939
A3: Name ▾ | B3: AvK | C3: BABIP | D3: Gap | E3: Power | F3: Eye | G3: Speed | H3: G | I3: W | J3: L | K3: Runs Scored | L3: Runs Allowed | M3: AB | N3: R | O3: H | P3: 2B | Q3: 3B | R3: HR | S3: RBI | T3: TB | U3: BB | V3: K | W3: SB | X3: CS | Y3: AVG | Z3: OBP | AA3: SLG | AB3: OPS | AC3: winpct | AD3: runs/G | AE3: win/162 delta | AF3: runs/162 delta | AG3: opp runs/G | AH3: PA | AI3: 1B% | AJ3: 2B% | AK3: 3B% | AL3: HR% | AM3: BB% | AN3: K% | AO3: GO+FO% | AP3: batR | AQ3: predicted wAA | AR3: wOBA | AS3: 1B% | AT3: 2B% | AU3: 3B% | AV3: HR% | AW3: BB% | AX3: K% | AY3: GO+FO% | BA3: 3137.4905 | BB3: -3014.1466 | BC3: -3103.0406 | BD3: 0 | BE3: -2218.353 | BF3: -3001.2948 | BG3: -3370.805 | BH3: -3321.7878
A4: Baseline 1 | B4: 50 | C4: 50 | D4: 50 | E4: 50 | F4: 50 | G4: 50 | H4: 100000 | I4: 50143 | J4: =H4-I4 -> 49857 | K4: 437889 | L4: 435152 | M4: 414165 | N4: 53378 | O4: 107676 | P4: 22094 | Q4: 1717 | R4: 11972 | S4: 44590 | T4: 169120 | U4: 33743 | V4: 96472 | W4: 3267 | X4: 2630 | Y4: 0.26 | Z4: 0.316 | AA4: 0.408 | AB4: 0.725 | AC4: =I4/H4 -> 0.50143 | AD4: =K4/H4 -> 4.37889 | AE4: n/a | AF4: n/a | AG4: =L4/H4 -> 4.35152 | AH4: =ROUND((M4+U4)*1.02,0) -> 456866 | AI4: =(O4-SUM(P4:R4))/$AH4 -> 0.15736124 | AJ4: =P4/$AH4 -> 0.048359913 | AK4: =Q4/$AH4 -> 0.0037582136 | AL4: =R4/$AH4 -> 0.02620462 | AM4: =U4/$AH4 -> 0.073857542 | AN4: =V4/$AH4 -> 0.21116038 | AO4: =1-SUM(AI4:AN4)-0.02 -> 0.45929809 | AR4: =SUMPRODUCT($AI$1:$AN$1,AI4:AN4) -> 0.31173066 | BA4: 0.27013526 | BB4: 0.097061319
A5: Baseline 2 | B5: 50 | C5: 50 | D5: 50 | E5: 50 | F5: 50 | G5: 50 | H5: 100000 | I5: 49981 | J5: =H5-I5 -> 50019 | K5: 437442 | L5: 436120 | M5: 414391 | N5: 52857 | O5: 107503 | P5: 21721 | Q5: 1753 | R5: 12048 | S5: 44566 | T5: 168874 | U5: 33526 | V5: 96560 | W5: 3281 | X5: 2746 | Y5: 0.259 | Z5: 0.316 | AA5: 0.408 | AB5: 0.723 | AC5: =I5/H5 -> 0.49981 | AD5: =K5/H5 -> 4.37442 | AE5: n/a | AF5: n/a | AG5: =L5/H5 -> 4.3612 | AH5: =ROUND((M5+U5)*1.02,0) -> 456875 | AI5: =(O5-SUM(P5:R5))/$AH5 -> 0.15755075 | AJ5: =P5/$AH5 -> 0.047542544 | AK5: =Q5/$AH5 -> 0.0038369357 | AL5: =R5/$AH5 -> 0.026370451 | AM5: =U5/$AH5 -> 0.073381122 | AN5: =V5/$AH5 -> 0.21134884 | AO5: =1-SUM(AI5:AN5)-0.02 -> 0.45996936 | AR5: =SUMPRODUCT($AI$1:$AN$1,AI5:AN5) -> 0.31099084
A6: Baseline 3 | B6: 50 | C6: 50 | D6: 50 | E6: 50 | F6: 50 | G6: 50 | H6: 100000 | I6: 50064 | J6: =H6-I6 -> 49936 | K6: 437105 | L6: 436245 | M6: 413881 | N6: 53300 | O6: 107503 | P6: 22131 | Q6: 1736 | R6: 12024 | S6: 44747 | T6: 169178 | U6: 33815 | V6: 97049 | W6: 3221 | X6: 2613 | Y6: 0.26 | Z6: 0.316 | AA6: 0.409 | AB6: 0.725 | AC6: =I6/H6 -> 0.50064 | AD6: =K6/H6 -> 4.37105 | AE6: n/a | AF6: n/a | AG6: =L6/H6 -> 4.36245 | AH6: =ROUND((M6+U6)*1.02,0) -> 456650 | AI6: =(O6-SUM(P6:R6))/$AH6 -> 0.15682032 | AJ6: =P6/$AH6 -> 0.048463813 | AK6: =Q6/$AH6 -> 0.0038015986 | AL6: =R6/$AH6 -> 0.026330888 | AM6: =U6/$AH6 -> 0.074050148 | AN6: =V6/$AH6 -> 0.21252381 | AO6: =1-SUM(AI6:AN6)-0.02 -> 0.45800942 | AR6: =SUMPRODUCT($AI$1:$AN$1,AI6:AN6) -> 0.31182525
A7: Baseline Average | B7: 50 | C7: 50 | D7: 50 | E7: 50 | F7: 50 | G7: 50 | H7: =AVERAGE(H4:H6) -> 100000 | I7: =AVERAGE(I4:I6) -> 50062.667 | J7: =H7-I7 -> 49937.333 | K7: =AVERAGE(K4:K6) -> 437478.67 | L7: =AVERAGE(L4:L6) -> 435839 | M7: =AVERAGE(M4:M6) -> 414145.67 | N7: =AVERAGE(N4:N6) -> 53178.333 | O7: =AVERAGE(O4:O6) -> 107560.67 | P7: =AVERAGE(P4:P6) -> 21982 | Q7: =AVERAGE(Q4:Q6) -> 1735.3333 | R7: =AVERAGE(R4:R6) -> 12014.667 | ... AB7: =AVERAGE(AB4:AB6) -> 0.72433333 | AC7: =I7/H7 -> 0.50062667 | AD7: =K7/H7 -> 4.3747867 | AE7: n/a | AF7: n/a | AG7: =AVERAGE(AG4:AG6) -> 4.35839 | AH7: =AVERAGE(AH4:AH6) -> 456797 | AI7: =AVERAGE(AI4:AI6) -> 0.1572441 | AJ7: =AVERAGE(AJ4:AJ6) -> 0.04812209 | AK7: =AVERAGE(AK4:AK6) -> 0.003798916 | AL7: =AVERAGE(AL4:AL6) -> 0.026301987 | AM7: =AVERAGE(AM4:AM6) -> 0.073762937 | AN7: =AVERAGE(AN4:AN6) -> 0.21167768 | AO7: =1-SUM(AI7:AN7)-0.02 -> 0.45909229 | AR7: =SUMPRODUCT($AI$1:$AN$1,AI7:AN7) -> 0.31151558
A8: Diabolical | B8: 20 | C8: 20 | D8: 20 | E8: 20 | F8: 20 | G8: 50 | H8: 100000 | I8: 45039 | J8: =H8-I8 -> 54961 | K8: 382270 | L8: 435927 | M8: 334620 | N8: 14558 | O8: 34945 | P8: 2941 | Q8: 194 | R8: 746 | S8: 8594 | T8: 40512 | U8: 4198 | V8: 171517 | W8: 1381 | X8: 1082 | Y8: 0.104 | Z8: 0.118 | AA8: 0.121 | AB8: 0.239 | AC8: =I8/H8 -> 0.45039 | AD8: =K8/H8 -> 3.8227 | AE8: =(AC8-$AC$7)*162 -> -8.13834 | AF8: =(AD8-$AD$7)*162 -> -89.43804 | AG8: =L8/H8 -> 4.35927 | AH8: =ROUND((M8+U8)*1.02,0) -> 345594 | AI8: =(O8-SUM(P8:R8))/$AH8 -> 0.08988582 | AJ8: =P8/$AH8 -> 0.0085099857 | AK8: =Q8/$AH8 -> 0.00056135234 | AL8: =R8/$AH8 -> 0.0021586023 | AM8: =U8/$AH8 -> 0.012147202 | AN8: =V8/$AH8 -> 0.49629623 | AO8: =1-SUM(AI8:AN8)-0.02 -> 0.37044081 | AP8: =$BA$3+SUMPRODUCT(AI8:AO8,$BB$3:$BH$3) -> -104.53481 | AQ8: =$BA$4+($BB$4*AP8) -> -9.8761511 | AR8: =SUMPRODUCT($AI$1:$AN$1,AI8:AN8) -> 0.10528059 | AS8: =AI8/AI$7 -> 0.57163237 | AT8: =AJ8/AJ$7 -> 0.17684157 | AU8: =AK8/AK$7 -> 0.14776645 | AV8: =AL8/AL$7 -> 0.082069934 | AW8: =AM8/AM$7 -> 0.16467893 | AX8: =AN8/AN$7 -> 2.3445846 | AY8: =AO8/AO$7 -> 0.80689834
A9: DiabolicalPower50 | B9: 20 | C9: 20 | D9: 20 | E9: 50 | F9: 20 | G9: 50 | H9: 100000 | I9: 46229 | J9: =H9-I9 -> 53771 | K9: 394284 | L9: 435735 | M9: 345054 | N9: 23763 | O9: 44006 | P9: 2765 | Q9: 180 | R9: 10157 | S9: 22750 | T9: 77602 | U9: 4317 | V9: 176749 | W9: 1326 | X9: 1017 | Y9: 0.128 | Z9: 0.141 | AA9: 0.225 | AB9: 0.366 | AC9: =I9/H9 -> 0.46229 | AD9: =K9/H9 -> 3.94284 | AE9: =(AC9-$AC$7)*162 -> -6.21054 | AF9: =(AD9-$AD$7)*162 -> -69.97536 | AG9: =L9/H9 -> 4.35735 | AH9: =ROUND((M9+U9)*1.02,0) -> 356358 | AI9: =(O9-SUM(P9:R9))/$AH9 -> 0.08672178 | AJ9: =P9/$AH9 -> 0.0077590513 | AK9: =Q9/$AH9 -> 0.00050511003 | AL9: =R9/$AH9 -> 0.028502237 | AM9: =U9/$AH9 -> 0.012114222 | AN9: =V9/$AH9 -> 0.49598718 | AO9: =1-SUM(AI9:AN9)-0.02 -> 0.34841042 | AP9: =$BA$3+SUMPRODUCT(AI9:AO9,$BB$3:$BH$3) -> -76.786226 | AQ9: =$BA$4+$BB$4*AP9 -> -7.1828371 | AR9: =SUMPRODUCT($AI$1:$AN$1,AI9:AN9) -> 0.1527604 | AS9: =AI9/AI$7 -> 0.55151053 | AT9: =AJ9/AJ$7 -> 0.16123679 | AU9: =AK9/AK$7 -> 0.13296162 | AV9: =AL9/AL$7 -> 1.0836534 | AW9: =AM9/AM$7 -> 0.16423183 | AX9: =AN9/AN$7 -> 2.3431246 | AY9: =AO9/AO$7 -> 0.75891151
A10: DiabolicalPower55 | B10: 20 | C10: 20 | D10: 20 | E10: 55 | F10: 20 | G10: 50 | H10: 100000 | I10: 46579 | J10: =H10-I10 -> 53421 | K10: 396772 | L10: 435682 | M10: 347172 | N10: 26279 | O10: 45923 | P10: 2657 | Q10: 213 | R10: 12688 | S10: 26144 | T10: 87070 | U10: 4412 | V10: 178373 | W10: 1368 | X10: 1058 | Y10: 0.132 | Z10: 0.146 | AA10: 0.251 | AB10: 0.397 | AC10: =I10/H10 -> 0.46579 | AD10: =K10/H10 -> 3.96772 | AE10: =(AC10-$AC$7)*162 -> -5.64354 | AF10: =(AD10-$AD$7)*162 -> -65.9448 | AG10: =L10/H10 -> 4.35682 | AH10: =ROUND((M10+U10)*1.02,0) -> 358616 | AI10: =(O10-SUM(P10:R10))/$AH10 -> 0.084672742 | AJ10: =P10/$AH10 -> 0.0074090392 | AK10: =Q10/$AH10 -> 0.00059395007 | AL10: =R10/$AH10 -> 0.035380463 | AM10: =U10/$AH10 -> 0.012302853 | AN10: =V10/$AH10 -> 0.49739275 | AO10: =1-SUM(AI10:AN10)-0.02 -> 0.3422482 | AP10: =$BA$3+SUMPRODUCT(AI10:AO10,$BB$3:$BH$3) -> -69.61682 | AQ10: =$BA$4+$BB$4*AP10 -> -6.4869651 | AR10: =SUMPRODUCT($AI$1:$AN$1,AI10:AN10) -> 0.16416919 | AS10: =AI10/AI$7 -> 0.5384796 | AT10: =AJ10/AJ$7 -> 0.15396337 | AU10: =AK10/AK$7 -> 0.15634725 | AV10: =AL10/AL$7 -> 1.3451631 | AW10: =AM10/AM$7 -> 0.16678909 | AX10: =AN10/AN$7 -> 2.3497648 | AY10: =AO10/AO$7 -> 0.74548889
A11: AVK20 | B11: 20 | C11: 50 | D11: 50 | E11: 50 | F11: 50 | G11: 50 | H11: 100000 | I11: 47491 | J11: =H11-I11 -> 52509 | K11: 407344 | L11: 434054 | M11: 381888 | N11: 38175 | O11: 65383 | P11: 12112 | Q11: 899 | R11: 11018 | S11: 30759 | T11: 112347 | U11: 30506 | V11: 196908 | W11: 2268 | X11: 1829 | Y11: 0.171 | Z11: 0.234 | AA11: 0.294 | AB11: 0.529 | AC11: =I11/H11 -> 0.47491 | AD11: =K11/H11 -> 4.07344 | AE11: =(AC11-$AC$7)*162 -> -4.1661 | AF11: =(AD11-$AD$7)*162 -> -48.81816 | AG11: =L11/H11 -> 4.34054 | AH11: =ROUND((M11+U11)*1.02,0) -> 420642 | AI11: =(O11-SUM(P11:R11))/$AH11 -> 0.098311628 | AJ11: =P11/$AH11 -> 0.028794081 | AK11: =Q11/$AH11 -> 0.0021372093 | AL11: =R11/$AH11 -> 0.026193295 | AM11: =U11/$AH11 -> 0.072522478 | AN11: =V11/$AH11 -> 0.46811303 | AO11: =1-SUM(AI11:AN11)-0.02 -> 0.28392828 | AP11: =$BA$3+SUMPRODUCT(AI11:AO11,$BB$3:$BH$3) -> -45.018901 | AQ11: =$BA$4+$BB$4*AP11 -> -4.0994587 | AR11: =SUMPRODUCT($AI$1:$AN$1,AI11:AN11) -> 0.23081228 | AS11: =AI11/AI$7 -> 0.62521663 | AT11: =AJ11/AJ$7 -> 0.59835476 | AU11: =AK11/AK$7 -> 0.56258399 | AV11: =AL11/AL$7 -> 0.99586755 | AW11: =AM11/AM$7 -> 0.98318316 | AX11: =AN11/AN$7 -> 2.2114426 | AY11: =AO11/AO$7 -> 0.61845579
A12: AVK25 | B12: 25 | C12: 50 | D12: 50 | E12: 50 | F12: 50 | G12: 50 | H12: 100000 | I12: 48291 | J12: =H12-I12 -> 51709 | K12: 417221 | L12: 434212 | M12: 404354 | N12: 44327 | O12: 83005 | P12: 16088 | Q12: 1231 | R12: 11599 | S12: 37046 | T12: 136352 | U12: 32373 | V12: 164423 | W12: 2640 | X12: 2187 | Y12: 0.205 | Z12: 0.266 | AA12: 0.337 | AB12: 0.603 | AC12: =I12/H12 -> 0.48291 | AD12: =K12/H12 -> 4.17221 | AE12: =(AC12-$AC$7)*162 -> -2.8701 | AF12: =(AD12-$AD$7)*162 -> -32.81742 | AG12: =L12/H12 -> 4.34212 | AH12: =ROUND((M12+U12)*1.02,0) -> 445462 | AI12: =(O12-SUM(P12:R12))/$AH12 -> 0.12141776 | AJ12: =P12/$AH12 -> 0.036115314 | AK12: =Q12/$AH12 -> 0.0027634231 | AL12: =R12/$AH12 -> 0.026038136 | AM12: =U12/$AH12 -> 0.072672865 | AN12: =V12/$AH12 -> 0.36910668 | AO12: =1-SUM(AI12:AN12)-0.02 -> 0.35188582 | AP12: =$BA$3+SUMPRODUCT(AI12:AO12,$BB$3:$BH$3) -> -29.498846 | AQ12: =$BA$4+$BB$4*AP12 -> -2.5930617 | AR12: =SUMPRODUCT($AI$1:$AN$1,AI12:AN12) -> 0.26146874 | AS12: =AI12/AI$7 -> 0.77216099 | AT12: =AJ12/AJ$7 -> 0.75049346 | AU12: =AK12/AK$7 -> 0.72742413 | AV12: =AL12/AL$7 -> 0.98996841 | AW12: =AM12/AM$7 -> 0.98522196 | AX12: =AN12/AN$7 -> 1.7437204 | AY12: =AO12/AO$7 -> 0.76648166
A13: AVK30 | B13: 30 | C13: 50 | D13: 50 | E13: 50 | F13: 50 | G13: 50 | H13: 100000 | I13: 48530 | J13: =H13-I13 -> 51470 | K13: 420121 | L13: 434355 | M13: 404968 | N13: 45908 | O13: 87544 | P13: 17007 | Q13: 1332 | R13: 11788 | S13: 38826 | T13: 142579 | U13: 32451 | V13: 149603 | W13: 2737 | X13: 2233 | Y13: 0.216 | Z13: 0.276 | AA13: 0.352 | AB13: 0.628 | AC13: =I13/H13 -> 0.4853 | AD13: =K13/H13 -> 4.20121 | AE13: =(AC13-$AC$7)*162 -> -2.48292 | AF13: =(AD13-$AD$7)*162 -> -28.11942 | AG13: =L13/H13 -> 4.34355 | AH13: =ROUND((M13+U13)*1.02,0) -> 446167 | AI13: =(O13-SUM(P13:R13))/$AH13 -> 0.12868948 | AJ13: =P13/$AH13 -> 0.038118014 | AK13: =Q13/$AH13 -> 0.0029854292 | AL13: =R13/$AH13 -> 0.0264206 | AM13: =U13/$AH13 -> 0.072732856 | AN13: =V13/$AH13 -> 0.33530718 | AO13: =1-SUM(AI13:AN13)-0.02 -> 0.37574644 | AP13: =$BA$3+SUMPRODUCT(AI13:AO13,$BB$3:$BH$3) -> -23.988215 | AQ13: =$BA$4+$BB$4*AP13 -> -2.0581925 | AR13: =SUMPRODUCT($AI$1:$AN$1,AI13:AN13) -> 0.27163197 | AS13: =AI13/AI$7 -> 0.81840577 | AT13: =AJ13/AJ$7 -> 0.79211053 | AU13: =AK13/AK$7 -> 0.78586346 | AV13: =AL13/AL$7 -> 1.0045097 | AW13: =AM13/AM$7 -> 0.98603524 | AX13: =AN13/AN$7 -> 1.584046 | AY13: =AO13/AO$7 -> 0.81845513
A14: AVK35 | B14: 35 | C14: 50 | D14: 50 | E14: 50 | F14: 50 | G14: 50 | H14: 100000 | I14: 48910 | J14: =H14-I14 -> 51090 | K14: 424356 | L14: 433982 | M14: 407326 | N14: 48253 | O14: 92928 | P14: 18382 | Q14: 1383 | R14: 12007 | S14: 40543 | T14: 150097 | U14: 32992 | V14: 135822 | W14: 2861 | X14: 2347 | Y14: 0.228 | Z14: 0.287 | AA14: 0.368 | AB14: 0.656 | AC14: =I14/H14 -> 0.4891 | AD14: =K14/H14 -> 4.24356 | AE14: =(AC14-$AC$7)*162 -> -1.86732 | AF14: =(AD14-$AD$7)*162 -> -21.25872 | AG14: =L14/H14 -> 4.33982 | AH14: =ROUND((M14+U14)*1.02,0) -> 449124 | AI14: =(O14-SUM(P14:R14))/$AH14 -> 0.13616729 | AJ14: =P14/$AH14 -> 0.040928563 | AK14: =Q14/$AH14 -> 0.0030793278 | AL14: =R14/$AH14 -> 0.026734265 | AM14: =U14/$AH14 -> 0.073458555 | AN14: =V14/$AH14 -> 0.30241537 | AO14: =1-SUM(AI14:AN14)-0.02 -> 0.39721663 | AP14: =$BA$3+SUMPRODUCT(AI14:AO14,$BB$3:$BH$3) -> -18.570065 | AQ14: =$BA$4+$BB$4*AP14 -> -1.5322998 | AR14: =SUMPRODUCT($AI$1:$AN$1,AI14:AN14) -> 0.28312771 | AS14: =AI14/AI$7 -> 0.86596121 | AT14: =AJ14/AJ$7 -> 0.85051508 | AU14: =AK14/AK$7 -> 0.81058065 | AV14: =AL14/AL$7 -> 1.0164352 | AW14: =AM14/AM$7 -> 0.9958735 | AX14: =AN14/AN$7 -> 1.4286597 | AY14: =AO14/AO$7 -> 0.86522174
A15: AVK40 | B15: 40 | C15: 50 | D15: 50 | E15: 50 | F15: 50 | G15: 50 | H15: 100000 | I15: 49429 | J15: =H15-I15 -> 50571 | K15: 429496 | L15: 435052 | M15: 411466 | N15: 50160 | O15: 99238 | P15: 19791 | Q15: 1537 | R15: 12052 | S15: 42464 | T15: 158259 | U15: 33322 | V15: 120970 | W15: 3151 | X15: 2473 | Y15: 0.241 | Z15: 0.299 | AA15: 0.385 | AB15: 0.684 | AC15: =I15/H15 -> 0.49429 | AD15: =K15/H15 -> 4.29496 | AE15: =(AC15-$AC$7)*162 -> -1.02654 | AF15: =(AD15-$AD$7)*162 -> -12.93192 | AG15: =L15/H15 -> 4.35052 | AH15: =ROUND((M15+U15)*1.02,0) -> 453684 | AI15: =(O15-SUM(P15:R15))/$AH15 -> 0.14516271 | AJ15: =P15/$AH15 -> 0.043622874 | AK15: =Q15/$AH15 -> 0.0033878206 | AL15: =R15/$AH15 -> 0.026564746 | AM15: =U15/$AH15 -> 0.073447598 | AN15: =V15/$AH15 -> 0.26663933 | AO15: =1-SUM(AI15:AN15)-0.02 -> 0.42117491 | AP15: =$BA$3+SUMPRODUCT(AI15:AO15,$BB$3:$BH$3) -> -12.625507 | AQ15: =$BA$4+$BB$4*AP15 -> -0.95531307 | AR15: =SUMPRODUCT($AI$1:$AN$1,AI15:AN15) -> 0.29470733 | AS15: =AI15/AI$7 -> 0.92316792 | AT15: =AJ15/AJ$7 -> 0.90650415 | AU15: =AK15/AK$7 -> 0.89178614 | AV15: =AL15/AL$7 -> 1.0099901 | AW15: =AM15/AM$7 -> 0.99572496 | AX15: =AN15/AN$7 -> 1.2596479 | AY15: =AO15/AO$7 -> 0.91740795
A16: AVK45 | B16: 45 | C16: 50 | D16: 50 | E16: 50 | F16: 50 | G16: 50 | H16: 100000 | I16: 49612 | J16: =H16-I16 -> 50388 | K16: 430723 | L16: 433896 | M16: 412767 | N16: 51151 | O16: 103302 | P16: 20931 | Q16: 1581 | R16: 11970 | S16: 43262 | T16: 163305 | U16: 33686 | V16: 107135 | W16: 3127 | X16: 2593 | Y16: 0.25 | Z16: 0.308 | AA16: 0.396 | AB16: 0.703 | AC16: =I16/H16 -> 0.49612 | AD16: =K16/H16 -> 4.30723 | AE16: =(AC16-$AC$7)*162 -> -0.73008 | AF16: =(AD16-$AD$7)*162 -> -10.94418 | AG16: =L16/H16 -> 4.33896 | AH16: =ROUND((M16+U16)*1.02,0) -> 455382 | AI16: =(O16-SUM(P16:R16))/$AH16 -> 0.15112587 | AJ16: =P16/$AH16 -> 0.045963609 | AK16: =Q16/$AH16 -> 0.0034718105 | AL16: =R16/$AH16 -> 0.026285624 | AM16: =U16/$AH16 -> 0.07397306 | AN16: =V16/$AH16 -> 0.23526402 | AO16: =1-SUM(AI16:AN16)-0.02 -> 0.44391601 | AP16: =$BA$3+SUMPRODUCT(AI16:AO16,$BB$3:$BH$3) -> -8.601623 | AQ16: =$BA$4+$BB$4*AP16 -> -0.56474961 | AR16: =SUMPRODUCT($AI$1:$AN$1,AI16:AN16) -> 0.30294175 | AS16: =AI16/AI$7 -> 0.96109084 | AT16: =AJ16/AJ$7 -> 0.95514573 | AU16: =AK16/AK$7 -> 0.91389505 | AV16: =AL16/AL$7 -> 0.9993779 | AW16: =AM16/AM$7 -> 1.0028486 | AX16: =AN16/AN$7 -> 1.1114257 | AY16: =AO16/AO$7 -> 0.96694286
A17: AVK55 | B17: 55 | C17: 50 | D17: 50 | E17: 50 | F17: 50 | G17: 50 | H17: 100000 | I17: 49993 | J17: =H17-I17 -> 50007 | K17: 436505 | L17: 435688 | M17: 416343 | N17: 53981 | O17: 111641 | P17: 22861 | Q17: 1766 | R17: 12162 | S17: 46077 | T17: 174520 | U17: 33620 | V17: 85754 | W17: 3441 | X17: 2618 | Y17: 0.268 | Z17: 0.323 | AA17: 0.419 | AB17: 0.743 | AC17: =I17/H17 -> 0.49993 | AD17: =K17/H17 -> 4.36505 | AE17: =(AC17-$AC$7)*162 -> -0.11286 | AF17: =(AD17-$AD$7)*162 -> -1.57734 | AG17: =L17/H17 -> 4.35688 | AH17: =ROUND((M17+U17)*1.02,0) -> 458962 | AI17: =(O17-SUM(P17:R17))/$AH17 -> 0.16308975 | AJ17: =P17/$AH17 -> 0.049810224 | AK17: =Q17/$AH17 -> 0.0038478131 | AL17: =R17/$AH17 -> 0.026498926 | AM17: =U17/$AH17 -> 0.073252252 | AN17: =V17/$AH17 -> 0.18684336 | AO17: =1-SUM(AI17:AN17)-0.02 -> 0.47665768 | AP17: =$BA$3+SUMPRODUCT(AI17:AO17,$BB$3:$BH$3) -> -0.4528035 | AQ17: =$BA$4+$BB$4*AP17 -> 0.22618555 | AR17: =SUMPRODUCT($AI$1:$AN$1,AI17:AN17) -> 0.31896257 | AS17: =AI17/AI$7 -> 1.0371756 | AT17: =AJ17/AJ$7 -> 1.0350802 | AU17: =AK17/AK$7 -> 1.0128713 | AV17: =AL17/AL$7 -> 1.0074876 | AW17: =AM17/AM$7 -> 0.99307666 | AX17: =AN17/AN$7 -> 0.88267859 | AY17: =AO17/AO$7 -> 1.0382611
A18: AVK60 | B18: 60 | C18: 50 | D18: 50 | E18: 50 | F18: 50 | G18: 50 | H18: 100000 | I18: 50247 | J18: =H18-I18 -> 49753 | K18: 439463 | L18: 435915 | M18: 417529 | N18: 54564 | O18: 114617 | P18: 23537 | Q18: 1865 | R18: 12187 | S18: 46814 | T18: 178445 | U18: 33465 | V18: 77091 | W18: 3438 | X18: 2684 | Y18: 0.275 | Z18: 0.329 | AA18: 0.427 | AB18: 0.756 | AC18: =I18/H18 -> 0.50247 | AD18: =K18/H18 -> 4.39463 | AE18: =(AC18-$AC$7)*162 -> 0.29862 | AF18: =(AD18-$AD$7)*162 -> 3.21462 | AG18: =L18/H18 -> 4.35915 | AH18: =ROUND((M18+U18)*1.02,0) -> 460014 | AI18: =(O18-SUM(P18:R18))/$AH18 -> 0.16744708 | AJ18: =P18/$AH18 -> 0.051165834 | AK18: =Q18/$AH18 -> 0.0040542244 | AL18: =R18/$AH18 -> 0.026492672 | AM18: =U18/$AH18 -> 0.072747786 | AN18: =V18/$AH18 -> 0.16758403 | AO18: =1-SUM(AI18:AN18)-0.02 -> 0.49050838 | AP18: =$BA$3+SUMPRODUCT(AI18:AO18,$BB$3:$BH$3) -> 2.6453394 | AQ18: =$BA$4+$BB$4*AP18 -> 0.52689539 | AR18: =SUMPRODUCT($AI$1:$AN$1,AI18:AN18) -> 0.32451171 | AS18: =AI18/AI$7 -> 1.0648862 | AT18: =AJ18/AJ$7 -> 1.0632505 | AU18: =AK18/AK$7 -> 1.0672056 | AV18: =AL18/AL$7 -> 1.0072498 | AW18: =AM18/AM$7 -> 0.98623765 | AX18: =AN18/AN$7 -> 0.79169439 | AY18: =AO18/AO$7 -> 1.0684309
A19: AVK65 | B19: 65 | C19: 50 | D19: 50 | E19: 50 | F19: 50 | G19: 50 | H19: 100000 | I19: 50630 | J19: =H19-I19 -> 49370 | K19: 439484 | L19: 435042 | M19: 418192 | N19: 55143 | O19: 117247 | P19: 24135 | Q19: 1865 | R19: 12167 | S19: 47226 | T19: 181613 | U19: 33135 | V19: 69074 | W19: 3507 | X19: 2739 | Y19: 0.28 | Z19: 0.334 | AA19: 0.434 | AB19: 0.768 | AC19: =I19/H19 -> 0.5063 | AD19: =K19/H19 -> 4.39484 | AE19: =(AC19-$AC$7)*162 -> 0.91908 | AF19: =(AD19-$AD$7)*162 -> 3.24864 | AG19: =L19/H19 -> 4.35042 | AH19: =ROUND((M19+U19)*1.02,0) -> 460354 | AI19: =(O19-SUM(P19:R19))/$AH19 -> 0.17178085 | AJ19: =P19/$AH19 -> 0.052427045 | AK19: =Q19/$AH19 -> 0.0040512301 | AL19: =R19/$AH19 -> 0.026429661 | AM19: =U19/$AH19 -> 0.071977218 | AN19: =V19/$AH19 -> 0.1500454 | AO19: =1-SUM(AI19:AN19)-0.02 -> 0.5032886 | AP19: =$BA$3+SUMPRODUCT(AI19:AO19,$BB$3:$BH$3) -> 4.7877299 | AQ19: =$BA$4+$BB$4*AP19 -> 0.73483863 | AR19: =SUMPRODUCT($AI$1:$AN$1,AI19:AN19) -> 0.32929365 | AS19: =AI19/AI$7 -> 1.092447 | AT19: =AJ19/AJ$7 -> 1.089459 | AU19: =AK19/AK$7 -> 1.0664174 | AV19: =AL19/AL$7 -> 1.0048542 | AW19: =AM19/AM$7 -> 0.9757911 | AX19: =AN19/AN$7 -> 0.70883903 | AY19: =AO19/AO$7 -> 1.0962689
A20: AVK70 | B20: 70 | C20: 50 | D20: 50 | E20: 50 | F20: 50 | G20: 50 | H20: 100000 | I20: 50979 | J20: =H20-I20 -> 49021 | K20: 444668 | L20: 434770 | M20: 418853 | N20: 56883 | O20: 120853 | P20: 24988 | Q20: 1960 | R20: 12320 | S20: 48950 | T20: 186721 | U20: 33675 | V20: 60039 | W20: 3650 | X20: 2838 | Y20: 0.289 | Z20: 0.342 | AA20: 0.446 | AB20: 0.788 | AC20: =I20/H20 -> 0.50979 | AD20: =K20/H20 -> 4.44668 | AE20: =(AC20-$AC$7)*162 -> 1.48446 | AF20: =(AD20-$AD$7)*162 -> 11.64672 | AG20: =L20/H20 -> 4.3477 | AH20: =ROUND((M20+U20)*1.02,0) -> 461579 | AI20: =(O20-SUM(P20:R20))/$AH20 -> 0.17675198 | AJ20: =P20/$AH20 -> 0.054135912 | AK20: =Q20/$AH20 -> 0.0042462937 | AL20: =R20/$AH20 -> 0.026690989 | AM20: =U20/$AH20 -> 0.072956092 | AN20: =V20/$AH20 -> 0.13007308 | AO20: =1-SUM(AI20:AN20)-0.02 -> 0.51514566 | AP20: =$BA$3+SUMPRODUCT(AI20:AO20,$BB$3:$BH$3) -> 8.9198925 | AQ20: =$BA$4+$BB$4*AP20 -> 1.1359118 | AR20: =SUMPRODUCT($AI$1:$AN$1,AI20:AN20) -> 0.33740534 | AS20: =AI20/AI$7 -> 1.1240611 | AT20: =AJ20/AJ$7 -> 1.1249701 | AU20: =AK20/AK$7 -> 1.1177646 | AV20: =AL20/AL$7 -> 1.0147899 | AW20: =AM20/AM$7 -> 0.98906164 | AX20: =AN20/AN$7 -> 0.6144865 | AY20: =AO20/AO$7 -> 1.1220961
... A108: SPD45 | B108: 50 | C108: 50 | D108: 50 | E108: 50 | F108: 50 | G108: 45 | H108: 100000 | I108: 49980 | J108: =H108-I108 -> 50020 | K108: 434067 | L108: 434303 | M108: 399785 | N108: 48827 | O108: 104402 | P108: 21756 | Q108: 1327 | R108: 11722 | S108: 52841 | T108: 163978 | U108: 32858 | V108: 94401 | W108: 1918 | X108: 1724 | Y108: 0.261 | Z108: 0.317 | AA108: 0.41 | AB108: 0.728 | AC108: =I108/H108 -> 0.4998 | AD108: =K108/H108 -> 4.34067 | AE108: =(AC108-$AC$7)*162 -> -0.13392 | AF108: =(AD108-$AD$7)*162 -> -5.5269 | AG108: =L108/H108 -> 4.34303 | AH108: =ROUND((M108+U108)*1.02,0) -> 441296 | AI108: =(O108-SUM(P108:R108))/$AH108 -> 0.15771047 | AJ108: =P108/$AH108 -> 0.049300243 | AK108: =Q108/$AH108 -> 0.003007052 | AL108: =R108/$AH108 -> 0.02656267 | AM108: =U108/$AH108 -> 0.07445796 | AN108: =V108/$AH108 -> 0.21391764 | AO108: =1-SUM(AI108:AN108)-0.02 -> 0.45504396 | AP108: =$BA$3+SUMPRODUCT(AI108:AO108,$BB$3:$BH$3) -> -5.882428 | AQ108: =$BA$4+$BB$4*AP108 -> -0.30082096 | AR108: =SUMPRODUCT($AI$1:$AN$1,AI108:AN108) -> 0.31316966 | AS108: =AI108/AI$7 -> 1.0029659 | AT108: =AJ108/AJ$7 -> 1.0244826 | AU108: =AK108/AK$7 -> 0.79155527 | AV108: =AL108/AL$7 -> 1.0099112 | AW108: =AM108/AM$7 -> 1.0094224 | AX108: =AN108/AN$7 -> 1.010582 | AY108: =AO108/AO$7 -> 0.99118189
A109: SPD55 | B109: 50 | C109: 50 | D109: 50 | E109: 50 | F109: 50 | G109: 55 | H109: 100000 | J109: =H109-I109 -> 100000 | AC109: =I109/H109 -> 0 | AD109: =K109/H109 -> 0 | AE109: =(AC109-$AC$7)*162 -> -81.10152 | AF109: =(AD109-$AD$7)*162 -> -708.71544 | AG109: =L109/H109 -> 0 | AH109: =ROUND((M109+U109)*1.02,0) -> 0 | AI109: =(O109-SUM(P109:R109))/$AH109 -> #DIV/0! | AJ109: =P109/$AH109 -> #DIV/0! | AK109: =Q109/$AH109 -> #DIV/0! | AL109: =R109/$AH109 -> #DIV/0! | AM109: =U109/$AH109 -> #DIV/0! | AN109: =V109/$AH109 -> #DIV/0! | AO109: =1-SUM(AI109:AN109)-0.02 -> #DIV/0! | AP109: =$BA$3+SUMPRODUCT(AI109:AO109,$BB$3:$BH$3) -> #DIV/0! | AQ109: =$BA$4+$BB$4*AP109 -> #DIV/0! | AR109: =SUMPRODUCT($AI$1:$AN$1,AI109:AN109) -> #DIV/0! | AS109: =AI109/AI$7 -> #DIV/0! | AT109: =AJ109/AJ$7 -> #DIV/0! | AU109: =AK109/AK$7 -> #DIV/0! | AV109: =AL109/AL$7 -> #DIV/0! | AW109: =AM109/AM$7 -> #DIV/0! | AX109: =AN109/AN$7 -> #DIV/0! | AY109: =AO109/AO$7 -> #DIV/0!
A110: SPD60 | B110: 50 | C110: 50 | D110: 50 | E110: 50 | F110: 50 | G110: 60 | H110: 100000 | J110: =H110-I110 -> 100000 | AC110: =I110/H110 -> 0 | AD110: =K110/H110 -> 0 | AE110: =(AC110-$AC$7)*162 -> -81.10152 | AF110: =(AD110-$AD$7)*162 -> -708.71544 | AG110: =L110/H110 -> 0 | AH110: =ROUND((M110+U110)*1.02,0) -> 0 | AI110: =(O110-SUM(P110:R110))/$AH110 -> #DIV/0! | AJ110: =P110/$AH110 -> #DIV/0! | AK110: =Q110/$AH110 -> #DIV/0! | AL110: =R110/$AH110 -> #DIV/0! | AM110: =U110/$AH110 -> #DIV/0! | AN110: =V110/$AH110 -> #DIV/0! | AO110: =1-SUM(AI110:AN110)-0.02 -> #DIV/0! | AP110: =$BA$3+SUMPRODUCT(AI110:AO110,$BB$3:$BH$3) -> #DIV/0! | AQ110: =$BA$4+$BB$4*AP110 -> #DIV/0! | AR110: =SUMPRODUCT($AI$1:$AN$1,AI110:AN110) -> #DIV/0! | AS110: =AI110/AI$7 -> #DIV/0! | AT110: =AJ110/AJ$7 -> #DIV/0! | AU110: =AK110/AK$7 -> #DIV/0! | AV110: =AL110/AL$7 -> #DIV/0! | AW110: =AM110/AM$7 -> #DIV/0! | AX110: =AN110/AN$7 -> #DIV/0! | AY110: =AO110/AO$7 -> #DIV/0!
A111: SPD65 | B111: 50 | C111: 50 | D111: 50 | E111: 50 | F111: 50 | G111: 65 | H111: 100000 | J111: =H111-I111 -> 100000 | AC111: =I111/H111 -> 0 | AD111: =K111/H111 -> 0 | AE111: =(AC111-$AC$7)*162 -> -81.10152 | AF111: =(AD111-$AD$7)*162 -> -708.71544 | AG111: =L111/H111 -> 0 | AH111: =ROUND((M111+U111)*1.02,0) -> 0 | AI111: =(O111-SUM(P111:R111))/$AH111 -> #DIV/0! | AJ111: =P111/$AH111 -> #DIV/0! | AK111: =Q111/$AH111 -> #DIV/0! | AL111: =R111/$AH111 -> #DIV/0! | AM111: =U111/$AH111 -> #DIV/0! | AN111: =V111/$AH111 -> #DIV/0! | AO111: =1-SUM(AI111:AN111)-0.02 -> #DIV/0! | AP111: =$BA$3+SUMPRODUCT(AI111:AO111,$BB$3:$BH$3) -> #DIV/0! | AQ111: =$BA$4+$BB$4*AP111 -> #DIV/0! | AR111: =SUMPRODUCT($AI$1:$AN$1,AI111:AN111) -> #DIV/0! | AS111: =AI111/AI$7 -> #DIV/0! | AT111: =AJ111/AJ$7 -> #DIV/0! | AU111: =AK111/AK$7 -> #DIV/0! | AV111: =AL111/AL$7 -> #DIV/0! | AW111: =AM111/AM$7 -> #DIV/0! | AX111: =AN111/AN$7 -> #DIV/0! | AY111: =AO111/AO$7 -> #DIV/0!
A112: SPD70 | B112: 50 | C112: 50 | D112: 50 | E112: 50 | F112: 50 | G112: 70 | H112: 100000 | J112: =H112-I112 -> 100000 | AC112: =I112/H112 -> 0 | AD112: =K112/H112 -> 0 | AE112: =(AC112-$AC$7)*162 -> -81.10152 | AF112: =(AD112-$AD$7)*162 -> -708.71544 | AG112: =L112/H112 -> 0 | AH112: =ROUND((M112+U112)*1.02,0) -> 0 | AI112: =(O112-SUM(P112:R112))/$AH112 -> #DIV/0! | AJ112: =P112/$AH112 -> #DIV/0! | AK112: =Q112/$AH112 -> #DIV/0! | AL112: =R112/$AH112 -> #DIV/0! | AM112: =U112/$AH112 -> #DIV/0! | AN112: =V112/$AH112 -> #DIV/0! | AO112: =1-SUM(AI112:AN112)-0.02 -> #DIV/0! | AP112: =$BA$3+SUMPRODUCT(AI112:AO112,$BB$3:$BH$3) -> #DIV/0! | AQ112: =$BA$4+$BB$4*AP112 -> #DIV/0! | AR112: =SUMPRODUCT($AI$1:$AN$1,AI112:AN112) -> #DIV/0! | AS112: =AI112/AI$7 -> #DIV/0! | AT112: =AJ112/AJ$7 -> #DIV/0! | AU112: =AK112/AK$7 -> #DIV/0! | AV112: =AL112/AL$7 -> #DIV/0! | AW112: =AM112/AM$7 -> #DIV/0! | AX112: =AN112/AN$7 -> #DIV/0! | AY112: =AO112/AO$7 -> #DIV/0!
A113: SPD75 | B113: 50 | C113: 50 | D113: 50 | E113: 50 | F113: 50 | G113: 75 | H113: 100000 | J113: =H113-I113 -> 100000 | AC113: =I113/H113 -> 0 | AD113: =K113/H113 -> 0 | AE113: =(AC113-$AC$7)*162 -> -81.10152 | AF113: =(AD113-$AD$7)*162 -> -708.71544 | AG113: =L113/H113 -> 0 | AH113: =ROUND((M113+U113)*1.02,0) -> 0 | AI113: =(O113-SUM(P113:R113))/$AH113 -> #DIV/0! | AJ113: =P113/$AH113 -> #DIV/0! | AK113: =Q113/$AH113 -> #DIV/0! | AL113: =R113/$AH113 -> #DIV/0! | AM113: =U113/$AH113 -> #DIV/0! | AN113: =V113/$AH113 -> #DIV/0! | AO113: =1-SUM(AI113:AN113)-0.02 -> #DIV/0! | AP113: =$BA$3+SUMPRODUCT(AI113:AO113,$BB$3:$BH$3) -> #DIV/0! | AQ113: =$BA$4+$BB$4*AP113 -> #DIV/0! | AR113: =SUMPRODUCT($AI$1:$AN$1,AI113:AN113) -> #DIV/0! | AS113: =AI113/AI$7 -> #DIV/0! | AT113: =AJ113/AJ$7 -> #DIV/0! | AU113: =AK113/AK$7 -> #DIV/0! | AV113: =AL113/AL$7 -> #DIV/0! | AW113: =AM113/AM$7 -> #DIV/0! | AX113: =AN113/AN$7 -> #DIV/0! | AY113: =AO113/AO$7 -> #DIV/0!
A114: SPD80 | B114: 50 | C114: 50 | D114: 50 | E114: 50 | F114: 50 | G114: 80 | H114: 100000 | J114: =H114-I114 -> 100000 | AC114: =I114/H114 -> 0 | AD114: =K114/H114 -> 0 | AE114: =(AC114-$AC$7)*162 -> -81.10152 | AF114: =(AD114-$AD$7)*162 -> -708.71544 | AG114: =L114/H114 -> 0 | AH114: =ROUND((M114+U114)*1.02,0) -> 0 | AI114: =(O114-SUM(P114:R114))/$AH114 -> #DIV/0! | AJ114: =P114/$AH114 -> #DIV/0! | AK114: =Q114/$AH114 -> #DIV/0! | AL114: =R114/$AH114 -> #DIV/0! | AM114: =U114/$AH114 -> #DIV/0! | AN114: =V114/$AH114 -> #DIV/0! | AO114: =1-SUM(AI114:AN114)-0.02 -> #DIV/0! | AP114: =$BA$3+SUMPRODUCT(AI114:AO114,$BB$3:$BH$3) -> #DIV/0! | AQ114: =$BA$4+$BB$4*AP114 -> #DIV/0! | AR114: =SUMPRODUCT($AI$1:$AN$1,AI114:AN114) -> #DIV/0! | AS114: =AI114/AI$7 -> #DIV/0! | AT114: =AJ114/AJ$7 -> #DIV/0! | AU114: =AK114/AK$7 -> #DIV/0! | AV114: =AL114/AL$7 -> #DIV/0! | AW114: =AM114/AM$7 -> #DIV/0! | AX114: =AN114/AN$7 -> #DIV/0! | AY114: =AO114/AO$7 -> #DIV/0!

Sheet Fielding
H2: Team A | I2: Team A | J2: Team A | K2: Team A | L2: Team A | M2: Team A | N2: Team A | O2: Team A | P2: Team A
A3: Position | B3: Name | C3: Range/Blocking | D3: Error/Framing | E3: Arm | F3: Turn DP | G3: Games | H3: W | I3: L | J3: Runs scored | K3: Runs allowed | L3: winpct | M3: run score/G | N3: run conc/G | O3: win/162 delta | P3: run/162 delta
A4: SS | B4: Baseline | C4: 60 | D4: 60 | E4: 55 | F4: 50 | G4: 100000 | H4: 50231 | I4: =G4-H4 -> 49769 | J4: 434612 | K4: 433939 | L4: =H4/G4 -> 0.50231 | M4: =J4/G4 -> 4.34612 | N4: =K4/G4 -> 4.33939
A5: SS | B5: Baseline | C5: 60 | D5: 60 | E5: 55 | F5: 50 | G5: 100000 | H5: 50093 | I5: =G5-H5 -> 49907 | J5: 434305 | K5: 433615 | L5: =H5/G5 -> 0.50093 | M5: =J5/G5 -> 4.34305 | N5: =K5/G5 -> 4.33615
A6: SS | B6: Baseline | C6: 60 | D6: 60 | E6: 55 | F6: 50 | G6: 100000 | H6: 50118 | I6: =G6-H6 -> 49882 | J6: 434377 | K6: 434430 | L6: =H6/G6 -> 0.50118 | M6: =J6/G6 -> 4.34377 | N6: =K6/G6 -> 4.3443
A7: SS | B7: Baseline Average | C7: 60 | D7: 60 | E7: 55 | F7: 50 | G7: 100000 | H7: =AVERAGE(H4:H6) -> 50147.333 | I7: =G7-H7 -> 49852.667 | J7: =AVERAGE(J4:J6) -> 434431.33 | K7: =AVERAGE(K4:K6) -> 433994.67 | L7: =H7/G7 -> 0.50147333 | M7: =J7/G7 -> 4.3443133 | N7: =K7/G7 -> 4.3399467 | O7: n/a | P7: n/a
A8: SS | B8: =_xlfn.CONCAT("RNG",C8,"xERR",D8,"xARM",E8,"xTDP",F8) -> RNG40xERR60xARM55xTDP50 | C8: 40 | D8: 60 | E8: 55 | F8: 50 | G8: 100000 | H8: 49543 | I8: =G8-H8 -> 50457 | J8: 434865 | K8: 440217 | L8: =H8/G8 -> 0.49543 | M8: =J8/G8 -> 4.34865 | N8: =K8/G8 -> 4.40217 | O8: =(L8-$L$7)*162 -> -0.97902 | P8: =-(N8-$N$7)*162 -> -10.08018
A9: SS | B9: =_xlfn.CONCAT("RNG",C9,"xERR",D9,"xARM",E9,"xTDP",F9) -> RNG45xERR60xARM55xTDP50 | C9: 45 | D9: 60 | E9: 55 | F9: 50 | G9: 100000 | H9: 49497 | I9: =G9-H9 -> 50503 | J9: 434811 | K9: 438342 | L9: =H9/G9 -> 0.49497 | M9: =J9/G9 -> 4.34811 | N9: =K9/G9 -> 4.38342 | O9: =(L9-$L$7)*162 -> -1.05354 | P9: =-(N9-$N$7)*162 -> -7.04268
A10: SS | B10: =_xlfn.CONCAT("RNG",C10,"xERR",D10,"xARM",E10,"xTDP",F10) -> RNG50xERR60xARM55xTDP50 | C10: 50 | D10: 60 | E10: 55 | F10: 50 | G10: 100000 | H10: 49215 | I10: =G10-H10 -> 50785 | J10: 433536 | K10: 440885 | L10: =H10/G10 -> 0.49215 | M10: =J10/G10 -> 4.33536 | N10: =K10/G10 -> 4.40885 | O10: =(L10-$L$7)*162 -> -1.51038 | P10: =-(N10-$N$7)*162 -> -11.16234
A11: SS | B11: =_xlfn.CONCAT("RNG",C11,"xERR",D11,"xARM",E11,"xTDP",F11) -> RNG55xERR60xARM55xTDP50 | C11: 55 | D11: 60 | E11: 55 | F11: 50 | G11: 100000 | H11: 49146 | I11: =G11-H11 -> 50854 | J11: 435444 | K11: 442064 | L11: =H11/G11 -> 0.49146 | M11: =J11/G11 -> 4.35444 | N11: =K11/G11 -> 4.42064 | O11: =(L11-$L$7)*162 -> -1.62216 | P11: =-(N11-$N$7)*162 -> -13.07232
A12: SS | B12: =_xlfn.CONCAT("RNG",C12,"xERR",D12,"xARM",E12,"xTDP",F12) -> RNG65xERR60xARM55xTDP50 | C12: 65 | D12: 60 | E12: 55 | F12: 50 | G12: 100000 | H12: 51849 | I12: =G12-H12 -> 48151 | J12: 434109 | K12: 416465 | L12: =H12/G12 -> 0.51849 | M12: =J12/G12 -> 4.34109 | N12: =K12/G12 -> 4.16465 | O12: =(L12-$L$7)*162 -> 2.7567 | P12: =-(N12-$N$7)*162 -> 28.39806
A13: SS | B13: =_xlfn.CONCAT("RNG",C13,"xERR",D13,"xARM",E13,"xTDP",F13) -> RNG70xERR60xARM55xTDP50 | C13: 70 | D13: 60 | E13: 55 | F13: 50 | G13: 100000 | H13: 51991 | I13: =G13-H13 -> 48009 | J13: 433680 | K13: 413888 | L13: =H13/G13 -> 0.51991 | M13: =J13/G13 -> 4.3368 | N13: =K13/G13 -> 4.13888 | O13: =(L13-$L$7)*162 -> 2.98674 | P13: =-(N13-$N$7)*162 -> 32.5728
A14: SS | B14: =_xlfn.CONCAT("RNG",C14,"xERR",D14,"xARM",E14,"xTDP",F14) -> RNG75xERR60xARM55xTDP50 | C14: 75 | D14: 60 | E14: 55 | F14: 50 | G14: 100000 | H14: 51814 | I14: =G14-H14 -> 48186 | J14: 431343 | K14: 413087 | L14: =H14/G14 -> 0.51814 | M14: =J14/G14 -> 4.31343 | N14: =K14/G14 -> 4.13087 | O14: =(L14-$L$7)*162 -> 2.7 | P14: =-(N14-$N$7)*162 -> 33.87042
A15: SS | B15: =_xlfn.CONCAT("RNG",C15,"xERR",D15,"xARM",E15,"xTDP",F15) -> RNG60xERR50xARM55xTDP50 | C15: 60 | D15: 50 | E15: 55 | F15: 50 | G15: 100000 | H15: 49866 | I15: =G15-H15 -> 50134 | J15: 434246 | K15: 436547 | L15: =H15/G15 -> 0.49866 | M15: =J15/G15 -> 4.34246 | N15: =K15/G15 -> 4.36547 | O15: =(L15-$L$7)*162 -> -0.45576 | P15: =-(N15-$N$7)*162 -> -4.13478
A16: SS | B16: =_xlfn.CONCAT("RNG",C16,"xERR",D16,"xARM",E16,"xTDP",F16) -> RNG60xERR55xARM55xTDP50 | C16: 60 | D16: 55 | E16: 55 | F16: 50 | G16: 100000 | H16: 49855 | I16: =G16-H16 -> 50145 | J16: 435110 | K16: 436472 | L16: =H16/G16 -> 0.49855 | M16: =J16/G16 -> 4.3511 | N16: =K16/G16 -> 4.36472 | O16: =(L16-$L$7)*162 -> -0.47358 | P16: =-(N16-$N$7)*162 -> -4.01328
A17: SS | B17: =_xlfn.CONCAT("RNG",C17,"xERR",D17,"xARM",E17,"xTDP",F17) -> RNG60xERR65xARM55xTDP50 | C17: 60 | D17: 65 | E17: 55 | F17: 50 | G17: 100000 | H17: 49965 | I17: =G17-H17 -> 50035 | J17: 435041 | K17: 434114 | L17: =H17/G17 -> 0.49965 | M17: =J17/G17 -> 4.35041 | N17: =K17/G17 -> 4.34114 | O17: =(L17-$L$7)*162 -> -0.29538 | P17: =-(N17-$N$7)*162 -> -0.19332
A18: SS | B18: =_xlfn.CONCAT("RNG",C18,"xERR",D18,"xARM",E18,"xTDP",F18) -> RNG60xERR70xARM55xTDP50 | C18: 60 | D18: 70 | E18: 55 | F18: 50 | G18: 100000 | H18: 50584 | I18: =G18-H18 -> 49416 | J18: 435999 | K18: 431954 | L18: =H18/G18 -> 0.50584 | M18: =J18/G18 -> 4.35999 | N18: =K18/G18 -> 4.31954 | O18: =(L18-$L$7)*162 -> 0.7074 | P18: =-(N18-$N$7)*162 -> 3.30588
A19: SS | B19: =_xlfn.CONCAT("RNG",C19,"xERR",D19,"xARM",E19,"xTDP",F19) -> RNG60xERR75xARM55xTDP50 | C19: 60 | D19: 75 | E19: 55 | F19: 50 | G19: 100000 | H19: 50331 | I19: =G19-H19 -> 49669 | J19: 436126 | K19: 432745 | L19: =H19/G19 -> 0.50331 | M19: =J19/G19 -> 4.36126 | N19: =K19/G19 -> 4.32745 | O19: =(L19-$L$7)*162 -> 0.29754 | P19: =-(N19-$N$7)*162 -> 2.02446
... A71: SS | B71: =_xlfn.CONCAT("RNG",C71,"xERR",D71,"xARM",E71,"xTDP",F71) -> RNG70xERR60xARM60xTDP50 | C71: 70 | D71: 60 | E71: 60 | F71: 50 | G71: 100000 | H71: 52140 | I71: =G71-H71 -> 47860 | J71: 434730 | K71: 414048 | L71: =H71/G71 -> 0.5214 | M71: =J71/G71 -> 4.3473 | N71: =K71/G71 -> 4.14048 | O71: =(L71-$L$7)*162 -> 3.22812 | P71: =-(N71-$N$7)*162 -> 32.3136
A72: 1B | B72: Baseline | C72: 35 | D72: 35 | E72: 40 | F72: 40 | G72: 100000 | H72: 50147.333 | I72: 49852.667 | J72: 434431.33 | K72: 433994.67 | L72: 0.50147333 | M72: 4.3443133 | N72: 4.3399467 | O72: n/a | P72: n/a
A73: 1B | B73: =_xlfn.CONCAT("RNG",C73,"xERR",D73,"xARM",E73,"xTDP",F73) -> RNG20xERR35xARM40xTDP40 | C73: 20 | D73: 35 | E73: 40 | F73: 40 | G73: 100000 | H73: 49785 | I73: =G73-H73 -> 50215 | J73: 431980 | K73: 435007 | L73: =H73/G73 -> 0.49785 | M73: =J73/G73 -> 4.3198 | N73: =K73/G73 -> 4.35007 | O73: =(L73-$L$7)*162 -> -0.58698 | P73: =-(N73-$N$7)*162 -> -1.63998
A74: 1B | B74: =_xlfn.CONCAT("RNG",C74,"xERR",D74,"xARM",E74,"xTDP",F74) -> RNG30xERR35xARM40xTDP40 | C74: 30 | D74: 35 | E74: 40 | F74: 40 | G74: 100000 | H74: 49649 | I74: =G74-H74 -> 50351 | J74: 434021 | K74: 436272 | L74: =H74/G74 -> 0.49649 | M74: =J74/G74 -> 4.34021 | N74: =K74/G74 -> 4.36272 | O74: =(L74-$L$7)*162 -> -0.8073 | P74: =-(N74-$N$7)*162 -> -3.68928
A75: 1B | B75: =_xlfn.CONCAT("RNG",C75,"xERR",D75,"xARM",E75,"xTDP",F75) -> RNG40xERR35xARM40xTDP40 | C75: 40 | D75: 35 | E75: 40 | F75: 40 | G75: 100000 | H75: 50370 | I75: =G75-H75 -> 49630 | J75: 435324 | K75: 433571 | L75: =H75/G75 -> 0.5037 | M75: =J75/G75 -> 4.35324 | N75: =K75/G75 -> 4.33571 | O75: =(L75-$L$7)*162 -> 0.36072 | P75: =-(N75-$N$7)*162 -> 0.68634
A76: 1B | B76: =_xlfn.CONCAT("RNG",C76,"xERR",D76,"xARM",E76,"xTDP",F76) -> RNG45xERR35xARM40xTDP40 | C76: 45 | D76: 35 | E76: 40 | F76: 40 | G76: 100000 | H76: 50354 | I76: =G76-H76 -> 49646 | J76: 432861 | K76: 431648 | L76: =H76/G76 -> 0.50354 | M76: =J76/G76 -> 4.32861 | N76: =K76/G76 -> 4.31648 | O76: =(L76-$L$7)*162 -> 0.3348 | P76: =-(N76-$N$7)*162 -> 3.8016
A77: 1B | B77: =_xlfn.CONCAT("RNG",C77,"xERR",D77,"xARM",E77,"xTDP",F77) -> RNG50xERR35xARM40xTDP40 | C77: 50 | D77: 35 | E77: 40 | F77: 40 | G77: 100000 | H77: 50084 | I77: =G77-H77 -> 49916 | J77: 435040 | K77: 433487 | L77: =H77/G77 -> 0.50084 | M77: =J77/G77 -> 4.3504 | N77: =K77/G77 -> 4.33487 | O77: =(L77-$L$7)*162 -> -0.1026 | P77: =-(N77-$N$7)*162 -> 0.82242
A78: 1B | B78: =_xlfn.CONCAT("RNG",C78,"xERR",D78,"xARM",E78,"xTDP",F78) -> RNG35xERR20xARM40xTDP40 | C78: 35 | D78: 20 | E78: 40 | F78: 40 | G78: 100000 | H78: 49809 | I78: =G78-H78 -> 50191 | J78: 433003 | K78: 435255 | L78: =H78/G78 -> 0.49809 | M78: =J78/G78 -> 4.33003 | N78: =K78/G78 -> 4.35255 | O78: =(L78-$L$7)*162 -> -0.5481 | P78: =-(N78-$N$7)*162 -> -2.04174
A79: 1B | B79: =_xlfn.CONCAT("RNG",C79,"xERR",D79,"xARM",E79,"xTDP",F79) -> RNG35xERR30xARM40xTDP40 | C79: 35 | D79: 30 | E79: 40 | F79: 40 | G79: 100000 | H79: 50204 | I79: =G79-H79 -> 49796 | J79: 434831 | K79: 433581 | L79: =H79/G79 -> 0.50204 | M79: =J79/G79 -> 4.34831 | N79: =K79/G79 -> 4.33581 | O79: =(L79-$L$7)*162 -> 0.0918 | P79: =-(N79-$N$7)*162 -> 0.67014
A80: 1B | B80: =_xlfn.CONCAT("RNG",C80,"xERR",D80,"xARM",E80,"xTDP",F80) -> RNG35xERR40xARM40xTDP40 | C80: 35 | D80: 40 | E80: 40 | F80: 40 | G80: 100000 | H80: 50104 | I80: =G80-H80 -> 49896 | J80: 433688 | K80: 433280 | L80: =H80/G80 -> 0.50104 | M80: =J80/G80 -> 4.33688 | N80: =K80/G80 -> 4.3328 | O80: =(L80-$L$7)*162 -> -0.0702 | P80: =-(N80-$N$7)*162 -> 1.15776
A81: 1B | B81: =_xlfn.CONCAT("RNG",C81,"xERR",D81,"xARM",E81,"xTDP",F81) -> RNG35xERR50xARM40xTDP40 | C81: 35 | D81: 50 | E81: 40 | F81: 40 | G81: 100000 | H81: 50127 | I81: =G81-H81 -> 49873 | J81: 434898 | K81: 435363 | L81: =H81/G81 -> 0.50127 | M81: =J81/G81 -> 4.34898 | N81: =K81/G81 -> 4.35363 | O81: =(L81-$L$7)*162 -> -0.03294 | P81: =-(N81-$N$7)*162 -> -2.2167
A82: 1B | B82: =_xlfn.CONCAT("RNG",C82,"xERR",D82,"xARM",E82,"xTDP",F82) -> RNG35xERR60xARM40xTDP40 | C82: 35 | D82: 60 | E82: 40 | F82: 40 | G82: 100000 | H82: 49836 | I82: =G82-H82 -> 50164 | J82: 434831 | K82: 435131 | L82: =H82/G82 -> 0.49836 | M82: =J82/G82 -> 4.34831 | N82: =K82/G82 -> 4.35131 | O82: =(L82-$L$7)*162 -> -0.50436 | P82: =-(N82-$N$7)*162 -> -1.84086
A83: 1B | B83: =_xlfn.CONCAT("RNG",C83,"xERR",D83,"xARM",E83,"xTDP",F83) -> RNG40xERR40xARM40xTDP40 | C83: 40 | D83: 40 | E83: 40 | F83: 40 | G83: 100000 | H83: 50112 | I83: =G83-H83 -> 49888 | J83: 434556 | K83: 433551 | L83: =H83/G83 -> 0.50112 | M83: =J83/G83 -> 4.34556 | N83: =K83/G83 -> 4.33551 | O83: =(L83-$L$7)*162 -> -0.05724 | P83: =-(N83-$N$7)*162 -> 0.71874
A84: 1B | B84: =_xlfn.CONCAT("RNG",C84,"xERR",D84,"xARM",E84,"xTDP",F84) -> RNG50xERR50xARM50xTDP50 | C84: 50 | D84: 50 | E84: 50 | F84: 50 | G84: 100000 | H84: 50163 | I84: =G84-H84 -> 49837 | J84: 433538 | K84: 431491 | L84: =H84/G84 -> 0.50163 | M84: =J84/G84 -> 4.33538 | N84: =K84/G84 -> 4.31491 | O84: =(L84-$L$7)*162 -> 0.02538 | P84: =-(N84-$N$7)*162 -> 4.05594
A85: 2B | B85: Baseline | C85: 50 | D85: 55 | E85: 50 | F85: 55 | G85: 100000 | H85: 50147.333 | I85: 49852.667 | J85: 434431.33 | K85: 433994.67 | L85: 0.50147333 | M85: 4.3443133 | N85: 4.3399467 | O85: n/a | P85: n/a
A86: 2B | B86: =_xlfn.CONCAT("RNG",C86,"xERR",D86,"xARM",E86,"xTDP",F86) -> RNG40xERR55xARM50xTDP55 | C86: 40 | D86: 55 | E86: 50 | F86: 55 | G86: 100000 | H86: 49985 | I86: =G86-H86 -> 50015 | J86: 435642 | K86: 436419 | L86: =H86/G86 -> 0.49985 | M86: =J86/G86 -> 4.35642 | N86: =K86/G86 -> 4.36419 | O86: =(L86-$L$7)*162 -> -0.26298 | P86: =-(N86-$N$7)*162 -> -3.92742
A87: 2B | B87: =_xlfn.CONCAT("RNG",C87,"xERR",D87,"xARM",E87,"xTDP",F87) -> RNG55xERR55xARM50xTDP55 | C87: 55 | D87: 55 | E87: 50 | F87: 55 | G87: 100000 | H87: 51016 | I87: =G87-H87 -> 48984 | J87: 435847 | K87: 426798 | L87: =H87/G87 -> 0.51016 | M87: =J87/G87 -> 4.35847 | N87: =K87/G87 -> 4.26798 | O87: =(L87-$L$7)*162 -> 1.40724 | P87: =-(N87-$N$7)*162 -> 11.6586
A88: 2B | B88: =_xlfn.CONCAT("RNG",C88,"xERR",D88,"xARM",E88,"xTDP",F88) -> RNG60xERR55xARM50xTDP55 | C88: 60 | D88: 55 | E88: 50 | F88: 55 | G88: 100000 | H88: 50816 | I88: =G88-H88 -> 49184 | J88: 434030 | K88: 426670 | L88: =H88/G88 -> 0.50816 | M88: =J88/G88 -> 4.3403 | N88: =K88/G88 -> 4.2667 | O88: =(L88-$L$7)*162 -> 1.08324 | P88: =-(N88-$N$7)*162 -> 11.86596
A89: 2B | B89: =_xlfn.CONCAT("RNG",C89,"xERR",D89,"xARM",E89,"xTDP",F89) -> RNG65xERR55xARM50xTDP55 | C89: 65 | D89: 55 | E89: 50 | F89: 55 | G89: 100000 | H89: 51001 | I89: =G89-H89 -> 48999 | J89: 433625 | K89: 425328 | L89: =H89/G89 -> 0.51001 | M89: =J89/G89 -> 4.33625 | N89: =K89/G89 -> 4.25328 | O89: =(L89-$L$7)*162 -> 1.38294 | P89: =-(N89-$N$7)*162 -> 14.04
A90: 2B | B90: =_xlfn.CONCAT("RNG",C90,"xERR",D90,"xARM",E90,"xTDP",F90) -> RNG70xERR55xARM50xTDP55 | C90: 70 | D90: 55 | E90: 50 | F90: 55 | G90: 100000 | H90: 50811 | I90: =G90-H90 -> 49189 | J90: 433670 | K90: 425315 | L90: =H90/G90 -> 0.50811 | M90: =J90/G90 -> 4.3367 | N90: =K90/G90 -> 4.25315 | O90: =(L90-$L$7)*162 -> 1.07514 | P90: =-(N90-$N$7)*162 -> 14.06106
A91: 2B | B91: =_xlfn.CONCAT("RNG",C91,"xERR",D91,"xARM",E91,"xTDP",F91) -> RNG75xERR55xARM50xTDP55 | C91: 75 | D91: 55 | E91: 50 | F91: 55 | G91: 100000 | H91: 50715 | I91: =G91-H91 -> 49285 | J91: 434090 | K91: 425781 | L91: =H91/G91 -> 0.50715 | M91: =J91/G91 -> 4.3409 | N91: =K91/G91 -> 4.25781 | O91: =(L91-$L$7)*162 -> 0.91962 | P91: =-(N91-$N$7)*162 -> 13.30614
A92: 2B | B92: =_xlfn.CONCAT("RNG",C92,"xERR",D92,"xARM",E92,"xTDP",F92) -> RNG50xERR40xARM50xTDP55 | C92: 50 | D92: 40 | E92: 50 | F92: 55 | G92: 100000 | H92: 49945 | I92: =G92-H92 -> 50055 | J92: 433834 | K92: 436366 | L92: =H92/G92 -> 0.49945 | M92: =J92/G92 -> 4.33834 | N92: =K92/G92 -> 4.36366 | O92: =(L92-$L$7)*162 -> -0.32778 | P92: =-(N92-$N$7)*162 -> -3.84156
...

Sheet Fielding recal
H2: Team A | I2: Team A | J2: Team A | K2: Team A | L2: Team A | M2: Team A | N2: Team A | O2: Team A | P2: Team A
A3: Position | B3: Name | C3: Range/Blocking | D3: Error/Framing | E3: Arm | F3: Turn DP | G3: Games | H3: W | I3: L | J3: Runs scored | K3: Runs allowed | L3: winpct | M3: run score/G | N3: run conc/G | O3: win/162 delta | P3: run/162 delta
B4: Baseline | G4: 100000 | H4: 49765 | I4: =G4-H4 -> 50235 | J4: 413894 | K4: 415919 | L4: =H4/G4 -> 0.49765 | M4: =J4/G4 -> 4.13894 | N4: =K4/G4 -> 4.15919
B5: Baseline | G5: 100000 | H5: 50092 | I5: =G5-H5 -> 49908 | J5: 414644 | K5: 414251 | L5: =H5/G5 -> 0.50092 | M5: =J5/G5 -> 4.14644 | N5: =K5/G5 -> 4.14251
B6: Baseline | G6: 100000 | H6: 49980 | I6: =G6-H6 -> 50020 | J6: 415709 | K6: 416539 | L6: =H6/G6 -> 0.4998 | M6: =J6/G6 -> 4.15709 | N6: =K6/G6 -> 4.16539
A7: C | B7: Baseline | C7: 55 | D7: 55 | E7: 55 | G7: 100000 | H7: 49945.667 | I7: 50054.333 | J7: 414749 | K7: 415569.67 | L7: 0.49945667 | M7: 4.14749 | N7: 4.1556967 | O7: n/a | P7: n/a
A8: C | B8: =_xlfn.CONCAT("BLK",C8,"xFRM",D8,"xARM",E8) -> BLK20xFRM20xARM20 | C8: 20 | D8: 20 | E8: 20 | G8: 100000 | H8: 46751 | I8: =G8-H8 -> 53249 | J8: 413786 | K8: 444647 | L8: =H8/G8 -> 0.46751 | M8: =J8/G8 -> 4.13786 | N8: =K8/G8 -> 4.44647 | O8: =(L8-$L$86)*162 -> -5.17536 | P8: =-(N8-$N$86)*162 -> -47.10528
